Workbook

Sheet 使い方
B1: チラシ進行台帳（Excel版）
C2: 学校ごとの工程管理と、価格・手数料バックの管理を1つのブックで行います。シート間は数式でつながっているので、「学校マスタ」に学校を足し、「価格」に商品を足すだけで、ガントも手数料集計も自動で追従します。
B4: シートの役割
B5: 学校マスタ | C5: 学校ごとに1行。工程のチェックと期日、協力企業、手数料バックの有無。ここが台帳の本体です。
B6: 価格 | C6: 学校×商品ごとに1行。PC機種もオプション品もここに登録します。手数料バックはこのシートで自動計算されます。
B7: ガント | C7: 学校マスタの日付から自動で帯を描きます。入力する場所はありません（開始日だけ変更できます）。
B8: 手数料集計 | C8: 協力企業ごとに、戻す手数料の見込みを集計します。全体のサマリーもここにあります。
B9: 設定 | C9: 担当・地区・協力企業・納品方法の選択肢。ここに足すと各シートのプルダウンに出ます。
B11: 入力する場所（セルの色）
B12: 青い文字 | C12: 手で入力する欄です。ここだけ触ってください。
B13: 黒い文字 | C13: 同じシート内の計算結果。上書きすると壊れます。
B14: 緑の文字 | C14: 他のシートを参照している計算結果。上書きすると壊れます。
B15: 黄色の背景 | C15: 最初に決めておく設定値（ガントの開始日など）。
B17: 使い方の順番
B18: 1. 設定 | C18: 担当者名・地区・協力企業・納品方法を先に登録します。
B19: 2. 学校マスタ | C19: 学校名から順に入力。日付を入れると状態とガントが自動で動きます。工程の「済」列はプルダウンで ✓ を選びます。
B20: 3. 価格 | C20: 学校名をプルダウンで選び、種別（PC／オプション）と品名、今年の掲載・卸・見込数量を入れます。
B21: 4. 手数料集計 | C21: 自動で集計されます。数字が合わないときは、価格シートの学校名が学校マスタと一致しているか確認してください。
B23: 手数料バックの計算
C24: 手数料バック単価 ＝ 今年 掲載（エンド税別） − 今年 卸（税別）。学校マスタの「手数料バック」を「なし」にすると、その学校の手数料は 0 になり、集計にも入りません。見込合計 ＝ 単価 × 見込 数量 です。
B26: 注意
B27: 学校名がキー | C27: 価格シートは学校名で学校マスタと結び付いています。学校名を変えるときは両方のシートを直してください（重複した学校名は使えません）。
B28: 行の追加 | C28: 数式は70校・250商品ぶん入れてあります。それ以上増やすときは、最終行をコピーして下に貼り付けてください。
B29: サンプル行 | C29: 1校ぶんのサンプルが入っています。実データを入れる前に削除してください（数式の列は消さずに、青文字の欄だけ消します）。

Sheet 設定
A1: 担当 | B1: 地区 | C1: 協力企業 | D1: 納品方法 | E1: 区分 | F1: 種別 | G1: 手数料バック
A2: 内野 | B2: 東京 | C2: サクラ電機販売 | D2: 一括納品（学校搬入） | E2: 継続 | F2: PC | G2: あり
A3: 佐藤 | B3: 神奈川 | C3: 三洋メディアサービス | D3: 個別配送（自宅） | E3: 新規開拓 | F3: オプション | G3: なし
A4: 高橋 | B4: 千葉 | C4: 日商テクノ商会 | D4: 説明会当日手渡し
A5: 森田 | B5: 埼玉 | C5: アイエス情報機器 | D5: 業者直送（分割）
A6: 岡本 | B6: 大阪 | C6: （協力企業なし）
B7: 愛知
B8: 福岡
B9: 北海道
B10: 宮城
B11: 広島
B12: 京都
B13: 兵庫
A20: ※ 各列に追記すると、他シートのプルダウンの選択肢が増えます（20行目まで対応）。

Sheet 学校マスタ
A1: 学校名 | B1: 地区 | C1: 担当 | D1: 区分 | E1: 生徒数 | F1: 協力企業 | G1: 手数料バック | H1: 機種提示日 | I1: 済 | J1: 意向回収期日 | K1: 済 | L1: EC公開期日 | M1: 済 | N1: ECサイトURL | O1: チラシ調整開始 | P1: チラシ調整終了 | Q1: 済 | R1: 販売開始日 | S1: 済 | T1: 納品方法 | U1: 納品期日 | V1: 済 | W1: 進捗 | X1: 状態 | Y1: 掲載機種数 | Z1: オプション点数 | AA1: 価格未入力 | AB1: 手数料バック見込 | AC1: メモ
A2: 青葉学園高等学校 | B2: 東京 | C2: 内野 | D2: 継続 | E2: 320 | F2: サクラ電機販売 | G2: あり | H2: 46211 | I2: ✓ | J2: 46228 | K2: ✓ | L2: 46238 | O2: 46235 | P2: 46245 | R2: 46248 | T2: 業者直送（分割） | U2: 46266 | V2: ✓ | W2: =IF($A2="","",(COUNTIF(I2,"✓")+ COUNTIF(K2,"✓")+ COUNTIF(M2,"✓")+ COUNTIF(Q2,"✓")+ COUNTIF(S2,"✓")+ COUNTIF(V2,"✓"))/6) | X2: =IF($A2="","",IF(W2=1,"完了",IF(OR(AND(I2<>"✓",H2<>"",H2<TODAY()),AND(K2<>"✓",J2<>"",J2<TODAY()),AND(M2<>"✓",L2<>"",L2<TODAY()),AND(Q2<>"✓",P2<>"",P2<TODAY()),AND(S2<>"✓",R2<>"",R2<TODAY()),AND(V2<>"✓",U2<>"",U2<TODAY())),"遅延",IF(OR(AND(I2<>"✓",H2<>"",H2<=TODAY()+7),AND(K2<>"✓",J2<>"",J2<=TODAY()+7),AND(M2<>"✓",L2<>"",L2<=TODAY()+7),AND(Q2<>"✓",P2<>"",P2<=TODAY()+7),AND(S2<>"✓",R2<>"",R2<=TODAY()+7),AND(V2<>"✓",U2<>"",U2<=TODAY()+7)),"今週対応","進行中")))) | Y2: =IF($A2="","",COUNTIFS(価格!$A$2:$A$251,$A2,価格!$B$2:$B$251,"PC")) | Z2: =IF($A2="","",COUNTIFS(価格!$A$2:$A$251,$A2,価格!$B$2:$B$251,"オプション")) | AA2: =IF($A2="","",COUNTIFS(価格!$A$2:$A$251,$A2)-COUNTIFS(価格!$A$2:$A$251,$A2,価格!$H$2:$H$251,">0",価格!$J$2:$J$251,">0")) | AB2: =IF($A2="","",SUMIFS(価格!$N$2:$N$251,価格!$A$2:$A$251,$A2)) | AC2: サンプル行です。実データを入れる前に削除してください。
W3: =IF($A3="","",(COUNTIF(I3,"✓")+ COUNTIF(K3,"✓")+ COUNTIF(M3,"✓")+ COUNTIF(Q3,"✓")+ COUNTIF(S3,"✓")+ COUNTIF(V3,"✓"))/6) | X3: =IF($A3="","",IF(W3=1,"完了",IF(OR(AND(I3<>"✓",H3<>"",H3<TODAY()),AND(K3<>"✓",J3<>"",J3<TODAY()),AND(M3<>"✓",L3<>"",L3<TODAY()),AND(Q3<>"✓",P3<>"",P3<TODAY()),AND(S3<>"✓",R3<>"",R3<TODAY()),AND(V3<>"✓",U3<>"",U3<TODAY())),"遅延",IF(OR(AND(I3<>"✓",H3<>"",H3<=TODAY()+7),AND(K3<>"✓",J3<>"",J3<=TODAY()+7),AND(M3<>"✓",L3<>"",L3<=TODAY()+7),AND(Q3<>"✓",P3<>"",P3<=TODAY()+7),AND(S3<>"✓",R3<>"",R3<=TODAY()+7),AND(V3<>"✓",U3<>"",U3<=TODAY()+7)),"今週対応","進行中")))) | Y3: =IF($A3="","",COUNTIFS(価格!$A$2:$A$251,$A3,価格!$B$2:$B$251,"PC")) | Z3: =IF($A3="","",COUNTIFS(価格!$A$2:$A$251,$A3,価格!$B$2:$B$251,"オプション")) | AA3: =IF($A3="","",COUNTIFS(価格!$A$2:$A$251,$A3)-COUNTIFS(価格!$A$2:$A$251,$A3,価格!$H$2:$H$251,">0",価格!$J$2:$J$251,">0")) | AB3: =IF($A3="","",SUMIFS(価格!$N$2:$N$251,価格!$A$2:$A$251,$A3))
W4: =IF($A4="","",(COUNTIF(I4,"✓")+ COUNTIF(K4,"✓")+ COUNTIF(M4,"✓")+ COUNTIF(Q4,"✓")+ COUNTIF(S4,"✓")+ COUNTIF(V4,"✓"))/6) | X4: =IF($A4="","",IF(W4=1,"完了",IF(OR(AND(I4<>"✓",H4<>"",H4<TODAY()),AND(K4<>"✓",J4<>"",J4<TODAY()),AND(M4<>"✓",L4<>"",L4<TODAY()),AND(Q4<>"✓",P4<>"",P4<TODAY()),AND(S4<>"✓",R4<>"",R4<TODAY()),AND(V4<>"✓",U4<>"",U4<TODAY())),"遅延",IF(OR(AND(I4<>"✓",H4<>"",H4<=TODAY()+7),AND(K4<>"✓",J4<>"",J4<=TODAY()+7),AND(M4<>"✓",L4<>"",L4<=TODAY()+7),AND(Q4<>"✓",P4<>"",P4<=TODAY()+7),AND(S4<>"✓",R4<>"",R4<=TODAY()+7),AND(V4<>"✓",U4<>"",U4<=TODAY()+7)),"今週対応","進行中")))) | Y4: =IF($A4="","",COUNTIFS(価格!$A$2:$A$251,$A4,価格!$B$2:$B$251,"PC")) | Z4: =IF($A4="","",COUNTIFS(価格!$A$2:$A$251,$A4,価格!$B$2:$B$251,"オプション")) | AA4: =IF($A4="","",COUNTIFS(価格!$A$2:$A$251,$A4)-COUNTIFS(価格!$A$2:$A$251,$A4,価格!$H$2:$H$251,">0",価格!$J$2:$J$251,">0")) | AB4: =IF($A4="","",SUMIFS(価格!$N$2:$N$251,価格!$A$2:$A$251,$A4))
W5: =IF($A5="","",(COUNTIF(I5,"✓")+ COUNTIF(K5,"✓")+ COUNTIF(M5,"✓")+ COUNTIF(Q5,"✓")+ COUNTIF(S5,"✓")+ COUNTIF(V5,"✓"))/6) | X5: =IF($A5="","",IF(W5=1,"完了",IF(OR(AND(I5<>"✓",H5<>"",H5<TODAY()),AND(K5<>"✓",J5<>"",J5<TODAY()),AND(M5<>"✓",L5<>"",L5<TODAY()),AND(Q5<>"✓",P5<>"",P5<TODAY()),AND(S5<>"✓",R5<>"",R5<TODAY()),AND(V5<>"✓",U5<>"",U5<TODAY())),"遅延",IF(OR(AND(I5<>"✓",H5<>"",H5<=TODAY()+7),AND(K5<>"✓",J5<>"",J5<=TODAY()+7),AND(M5<>"✓",L5<>"",L5<=TODAY()+7),AND(Q5<>"✓",P5<>"",P5<=TODAY()+7),AND(S5<>"✓",R5<>"",R5<=TODAY()+7),AND(V5<>"✓",U5<>"",U5<=TODAY()+7)),"今週対応","進行中")))) | Y5: =IF($A5="","",COUNTIFS(価格!$A$2:$A$251,$A5,価格!$B$2:$B$251,"PC")) | Z5: =IF($A5="","",COUNTIFS(価格!$A$2:$A$251,$A5,価格!$B$2:$B$251,"オプション")) | AA5: =IF($A5="","",COUNTIFS(価格!$A$2:$A$251,$A5)-COUNTIFS(価格!$A$2:$A$251,$A5,価格!$H$2:$H$251,">0",価格!$J$2:$J$251,">0")) | AB5: =IF($A5="","",SUMIFS(価格!$N$2:$N$251,価格!$A$2:$A$251,$A5))
W6: =IF($A6="","",(COUNTIF(I6,"✓")+ COUNTIF(K6,"✓")+ COUNTIF(M6,"✓")+ COUNTIF(Q6,"✓")+ COUNTIF(S6,"✓")+ COUNTIF(V6,"✓"))/6) | X6: =IF($A6="","",IF(W6=1,"完了",IF(OR(AND(I6<>"✓",H6<>"",H6<TODAY()),AND(K6<>"✓",J6<>"",J6<TODAY()),AND(M6<>"✓",L6<>"",L6<TODAY()),AND(Q6<>"✓",P6<>"",P6<TODAY()),AND(S6<>"✓",R6<>"",R6<TODAY()),AND(V6<>"✓",U6<>"",U6<TODAY())),"遅延",IF(OR(AND(I6<>"✓",H6<>"",H6<=TODAY()+7),AND(K6<>"✓",J6<>"",J6<=TODAY()+7),AND(M6<>"✓",L6<>"",L6<=TODAY()+7),AND(Q6<>"✓",P6<>"",P6<=TODAY()+7),AND(S6<>"✓",R6<>"",R6<=TODAY()+7),AND(V6<>"✓",U6<>"",U6<=TODAY()+7)),"今週対応","進行中")))) | Y6: =IF($A6="","",COUNTIFS(価格!$A$2:$A$251,$A6,価格!$B$2:$B$251,"PC")) | Z6: =IF($A6="","",COUNTIFS(価格!$A$2:$A$251,$A6,価格!$B$2:$B$251,"オプション")) | AA6: =IF($A6="","",COUNTIFS(価格!$A$2:$A$251,$A6)-COUNTIFS(価格!$A$2:$A$251,$A6,価格!$H$2:$H$251,">0",価格!$J$2:$J$251,">0")) | AB6: =IF($A6="","",SUMIFS(価格!$N$2:$N$251,価格!$A$2:$A$251,$A6))
W7: =IF($A7="","",(COUNTIF(I7,"✓")+ COUNTIF(K7,"✓")+ COUNTIF(M7,"✓")+ COUNTIF(Q7,"✓")+ COUNTIF(S7,"✓")+ COUNTIF(V7,"✓"))/6) | X7: =IF($A7="","",IF(W7=1,"完了",IF(OR(AND(I7<>"✓",H7<>"",H7<TODAY()),AND(K7<>"✓",J7<>"",J7<TODAY()),AND(M7<>"✓",L7<>"",L7<TODAY()),AND(Q7<>"✓",P7<>"",P7<TODAY()),AND(S7<>"✓",R7<>"",R7<TODAY()),AND(V7<>"✓",U7<>"",U7<TODAY())),"遅延",IF(OR(AND(I7<>"✓",H7<>"",H7<=TODAY()+7),AND(K7<>"✓",J7<>"",J7<=TODAY()+7),AND(M7<>"✓",L7<>"",L7<=TODAY()+7),AND(Q7<>"✓",P7<>"",P7<=TODAY()+7),AND(S7<>"✓",R7<>"",R7<=TODAY()+7),AND(V7<>"✓",U7<>"",U7<=TODAY()+7)),"今週対応","進行中")))) | Y7: =IF($A7="","",COUNTIFS(価格!$A$2:$A$251,$A7,価格!$B$2:$B$251,"PC")) | Z7: =IF($A7="","",COUNTIFS(価格!$A$2:$A$251,$A7,価格!$B$2:$B$251,"オプション")) | AA7: =IF($A7="","",COUNTIFS(価格!$A$2:$A$251,$A7)-COUNTIFS(価格!$A$2:$A$251,$A7,価格!$H$2:$H$251,">0",価格!$J$2:$J$251,">0")) | AB7: =IF($A7="","",SUMIFS(価格!$N$2:$N$251,価格!$A$2:$A$251,$A7))
W8: =IF($A8="","",(COUNTIF(I8,"✓")+ COUNTIF(K8,"✓")+ COUNTIF(M8,"✓")+ COUNTIF(Q8,"✓")+ COUNTIF(S8,"✓")+ COUNTIF(V8,"✓"))/6) | X8: =IF($A8="","",IF(W8=1,"完了",IF(OR(AND(I8<>"✓",H8<>"",H8<TODAY()),AND(K8<>"✓",J8<>"",J8<TODAY()),AND(M8<>"✓",L8<>"",L8<TODAY()),AND(Q8<>"✓",P8<>"",P8<TODAY()),AND(S8<>"✓",R8<>"",R8<TODAY()),AND(V8<>"✓",U8<>"",U8<TODAY())),"遅延",IF(OR(AND(I8<>"✓",H8<>"",H8<=TODAY()+7),AND(K8<>"✓",J8<>"",J8<=TODAY()+7),AND(M8<>"✓",L8<>"",L8<=TODAY()+7),AND(Q8<>"✓",P8<>"",P8<=TODAY()+7),AND(S8<>"✓",R8<>"",R8<=TODAY()+7),AND(V8<>"✓",U8<>"",U8<=TODAY()+7)),"今週対応","進行中")))) | Y8: =IF($A8="","",COUNTIFS(価格!$A$2:$A$251,$A8,価格!$B$2:$B$251,"PC")) | Z8: =IF($A8="","",COUNTIFS(価格!$A$2:$A$251,$A8,価格!$B$2:$B$251,"オプション")) | AA8: =IF($A8="","",COUNTIFS(価格!$A$2:$A$251,$A8)-COUNTIFS(価格!$A$2:$A$251,$A8,価格!$H$2:$H$251,">0",価格!$J$2:$J$251,">0")) | AB8: =IF($A8="","",SUMIFS(価格!$N$2:$N$251,価格!$A$2:$A$251,$A8))
W9: =IF($A9="","",(COUNTIF(I9,"✓")+ COUNTIF(K9,"✓")+ COUNTIF(M9,"✓")+ COUNTIF(Q9,"✓")+ COUNTIF(S9,"✓")+ COUNTIF(V9,"✓"))/6) | X9: =IF($A9="","",IF(W9=1,"完了",IF(OR(AND(I9<>"✓",H9<>"",H9<TODAY()),AND(K9<>"✓",J9<>"",J9<TODAY()),AND(M9<>"✓",L9<>"",L9<TODAY()),AND(Q9<>"✓",P9<>"",P9<TODAY()),AND(S9<>"✓",R9<>"",R9<TODAY()),AND(V9<>"✓",U9<>"",U9<TODAY())),"遅延",IF(OR(AND(I9<>"✓",H9<>"",H9<=TODAY()+7),AND(K9<>"✓",J9<>"",J9<=TODAY()+7),AND(M9<>"✓",L9<>"",L9<=TODAY()+7),AND(Q9<>"✓",P9<>"",P9<=TODAY()+7),AND(S9<>"✓",R9<>"",R9<=TODAY()+7),AND(V9<>"✓",U9<>"",U9<=TODAY()+7)),"今週対応","進行中")))) | Y9: =IF($A9="","",COUNTIFS(価格!$A$2:$A$251,$A9,価格!$B$2:$B$251,"PC")) | Z9: =IF($A9="","",COUNTIFS(価格!$A$2:$A$251,$A9,価格!$B$2:$B$251,"オプション")) | AA9: =IF($A9="","",COUNTIFS(価格!$A$2:$A$251,$A9)-COUNTIFS(価格!$A$2:$A$251,$A9,価格!$H$2:$H$251,">0",価格!$J$2:$J$251,">0")) | AB9: =IF($A9="","",SUMIFS(価格!$N$2:$N$251,価格!$A$2:$A$251,$A9))
W10: =IF($A10="","",(COUNTIF(I10,"✓")+ COUNTIF(K10,"✓")+ COUNTIF(M10,"✓")+ COUNTIF(Q10,"✓")+ COUNTIF(S10,"✓")+ COUNTIF(V10,"✓"))/6) | X10: =IF($A10="","",IF(W10=1,"完了",IF(OR(AND(I10<>"✓",H10<>"",H10<TODAY()),AND(K10<>"✓",J10<>"",J10<TODAY()),AND(M10<>"✓",L10<>"",L10<TODAY()),AND(Q10<>"✓",P10<>"",P10<TODAY()),AND(S10<>"✓",R10<>"",R10<TODAY()),AND(V10<>"✓",U10<>"",U10<TODAY())),"遅延",IF(OR(AND(I10<>"✓",H10<>"",H10<=TODAY()+7),AND(K10<>"✓",J10<>"",J10<=TODAY()+7),AND(M10<>"✓",L10<>"",L10<=TODAY()+7),AND(Q10<>"✓",P10<>"",P10<=TODAY()+7),AND(S10<>"✓",R10<>"",R10<=TODAY()+7),AND(V10<>"✓",U10<>"",U10<=TODAY()+7)),"今週対応","進行中")))) | Y10: =IF($A10="","",COUNTIFS(価格!$A$2:$A$251,$A10,価格!$B$2:$B$251,"PC")) | Z10: =IF($A10="","",COUNTIFS(価格!$A$2:$A$251,$A10,価格!$B$2:$B$251,"オプション")) | AA10: =IF($A10="","",COUNTIFS(価格!$A$2:$A$251,$A10)-COUNTIFS(価格!$A$2:$A$251,$A10,価格!$H$2:$H$251,">0",価格!$J$2:$J$251,">0")) | AB10: =IF($A10="","",SUMIFS(価格!$N$2:$N$251,価格!$A$2:$A$251,$A10))
W11: =IF($A11="","",(COUNTIF(I11,"✓")+ COUNTIF(K11,"✓")+ COUNTIF(M11,"✓")+ COUNTIF(Q11,"✓")+ COUNTIF(S11,"✓")+ COUNTIF(V11,"✓"))/6) | X11: =IF($A11="","",IF(W11=1,"完了",IF(OR(AND(I11<>"✓",H11<>"",H11<TODAY()),AND(K11<>"✓",J11<>"",J11<TODAY()),AND(M11<>"✓",L11<>"",L11<TODAY()),AND(Q11<>"✓",P11<>"",P11<TODAY()),AND(S11<>"✓",R11<>"",R11<TODAY()),AND(V11<>"✓",U11<>"",U11<TODAY())),"遅延",IF(OR(AND(I11<>"✓",H11<>"",H11<=TODAY()+7),AND(K11<>"✓",J11<>"",J11<=TODAY()+7),AND(M11<>"✓",L11<>"",L11<=TODAY()+7),AND(Q11<>"✓",P11<>"",P11<=TODAY()+7),AND(S11<>"✓",R11<>"",R11<=TODAY()+7),AND(V11<>"✓",U11<>"",U11<=TODAY()+7)),"今週対応","進行中")))) | Y11: =IF($A11="","",COUNTIFS(価格!$A$2:$A$251,$A11,価格!$B$2:$B$251,"PC")) | Z11: =IF($A11="","",COUNTIFS(価格!$A$2:$A$251,$A11,価格!$B$2:$B$251,"オプション")) | AA11: =IF($A11="","",COUNTIFS(価格!$A$2:$A$251,$A11)-COUNTIFS(価格!$A$2:$A$251,$A11,価格!$H$2:$H$251,">0",価格!$J$2:$J$251,">0")) | AB11: =IF($A11="","",SUMIFS(価格!$N$2:$N$251,価格!$A$2:$A$251,$A11))
W12: =IF($A12="","",(COUNTIF(I12,"✓")+ COUNTIF(K12,"✓")+ COUNTIF(M12,"✓")+ COUNTIF(Q12,"✓")+ COUNTIF(S12,"✓")+ COUNTIF(V12,"✓"))/6) | X12: =IF($A12="","",IF(W12=1,"完了",IF(OR(AND(I12<>"✓",H12<>"",H12<TODAY()),AND(K12<>"✓",J12<>"",J12<TODAY()),AND(M12<>"✓",L12<>"",L12<TODAY()),AND(Q12<>"✓",P12<>"",P12<TODAY()),AND(S12<>"✓",R12<>"",R12<TODAY()),AND(V12<>"✓",U12<>"",U12<TODAY())),"遅延",IF(OR(AND(I12<>"✓",H12<>"",H12<=TODAY()+7),AND(K12<>"✓",J12<>"",J12<=TODAY()+7),AND(M12<>"✓",L12<>"",L12<=TODAY()+7),AND(Q12<>"✓",P12<>"",P12<=TODAY()+7),AND(S12<>"✓",R12<>"",R12<=TODAY()+7),AND(V12<>"✓",U12<>"",U12<=TODAY()+7)),"今週対応","進行中")))) | Y12: =IF($A12="","",COUNTIFS(価格!$A$2:$A$251,$A12,価格!$B$2:$B$251,"PC")) | Z12: =IF($A12="","",COUNTIFS(価格!$A$2:$A$251,$A12,価格!$B$2:$B$251,"オプション")) | AA12: =IF($A12="","",COUNTIFS(価格!$A$2:$A$251,$A12)-COUNTIFS(価格!$A$2:$A$251,$A12,価格!$H$2:$H$251,">0",価格!$J$2:$J$251,">0")) | AB12: =IF($A12="","",SUMIFS(価格!$N$2:$N$251,価格!$A$2:$A$251,$A12))
W13: =IF($A13="","",(COUNTIF(I13,"✓")+ COUNTIF(K13,"✓")+ COUNTIF(M13,"✓")+ COUNTIF(Q13,"✓")+ COUNTIF(S13,"✓")+ COUNTIF(V13,"✓"))/6) | X13: =IF($A13="","",IF(W13=1,"完了",IF(OR(AND(I13<>"✓",H13<>"",H13<TODAY()),AND(K13<>"✓",J13<>"",J13<TODAY()),AND(M13<>"✓",L13<>"",L13<TODAY()),AND(Q13<>"✓",P13<>"",P13<TODAY()),AND(S13<>"✓",R13<>"",R13<TODAY()),AND(V13<>"✓",U13<>"",U13<TODAY())),"遅延",IF(OR(AND(I13<>"✓",H13<>"",H13<=TODAY()+7),AND(K13<>"✓",J13<>"",J13<=TODAY()+7),AND(M13<>"✓",L13<>"",L13<=TODAY()+7),AND(Q13<>"✓",P13<>"",P13<=TODAY()+7),AND(S13<>"✓",R13<>"",R13<=TODAY()+7),AND(V13<>"✓",U13<>"",U13<=TODAY()+7)),"今週対応","進行中")))) | Y13: =IF($A13="","",COUNTIFS(価格!$A$2:$A$251,$A13,価格!$B$2:$B$251,"PC")) | Z13: =IF($A13="","",COUNTIFS(価格!$A$2:$A$251,$A13,価格!$B$2:$B$251,"オプション")) | AA13: =IF($A13="","",COUNTIFS(価格!$A$2:$A$251,$A13)-COUNTIFS(価格!$A$2:$A$251,$A13,価格!$H$2:$H$251,">0",価格!$J$2:$J$251,">0")) | AB13: =IF($A13="","",SUMIFS(価格!$N$2:$N$251,価格!$A$2:$A$251,$A13))
W14: =IF($A14="","",(COUNTIF(I14,"✓")+ COUNTIF(K14,"✓")+ COUNTIF(M14,"✓")+ COUNTIF(Q14,"✓")+ COUNTIF(S14,"✓")+ COUNTIF(V14,"✓"))/6) | X14: =IF($A14="","",IF(W14=1,"完了",IF(OR(AND(I14<>"✓",H14<>"",H14<TODAY()),AND(K14<>"✓",J14<>"",J14<TODAY()),AND(M14<>"✓",L14<>"",L14<TODAY()),AND(Q14<>"✓",P14<>"",P14<TODAY()),AND(S14<>"✓",R14<>"",R14<TODAY()),AND(V14<>"✓",U14<>"",U14<TODAY())),"遅延",IF(OR(AND(I14<>"✓",H14<>"",H14<=TODAY()+7),AND(K14<>"✓",J14<>"",J14<=TODAY()+7),AND(M14<>"✓",L14<>"",L14<=TODAY()+7),AND(Q14<>"✓",P14<>"",P14<=TODAY()+7),AND(S14<>"✓",R14<>"",R14<=TODAY()+7),AND(V14<>"✓",U14<>"",U14<=TODAY()+7)),"今週対応","進行中")))) | Y14: =IF($A14="","",COUNTIFS(価格!$A$2:$A$251,$A14,価格!$B$2:$B$251,"PC")) | Z14: =IF($A14="","",COUNTIFS(価格!$A$2:$A$251,$A14,価格!$B$2:$B$251,"オプション")) | AA14: =IF($A14="","",COUNTIFS(価格!$A$2:$A$251,$A14)-COUNTIFS(価格!$A$2:$A$251,$A14,価格!$H$2:$H$251,">0",価格!$J$2:$J$251,">0")) | AB14: =IF($A14="","",SUMIFS(価格!$N$2:$N$251,価格!$A$2:$A$251,$A14))
... W71: =IF($A71="","",(COUNTIF(I71,"✓")+ COUNTIF(K71,"✓")+ COUNTIF(M71,"✓")+ COUNTIF(Q71,"✓")+ COUNTIF(S71,"✓")+ COUNTIF(V71,"✓"))/6) | X71: =IF($A71="","",IF(W71=1,"完了",IF(OR(AND(I71<>"✓",H71<>"",H71<TODAY()),AND(K71<>"✓",J71<>"",J71<TODAY()),AND(M71<>"✓",L71<>"",L71<TODAY()),AND(Q71<>"✓",P71<>"",P71<TODAY()),AND(S71<>"✓",R71<>"",R71<TODAY()),AND(V71<>"✓",U71<>"",U71<TODAY())),"遅延",IF(OR(AND(I71<>"✓",H71<>"",H71<=TODAY()+7),AND(K71<>"✓",J71<>"",J71<=TODAY()+7),AND(M71<>"✓",L71<>"",L71<=TODAY()+7),AND(Q71<>"✓",P71<>"",P71<=TODAY()+7),AND(S71<>"✓",R71<>"",R71<=TODAY()+7),AND(V71<>"✓",U71<>"",U71<=TODAY()+7)),"今週対応","進行中")))) | Y71: =IF($A71="","",COUNTIFS(価格!$A$2:$A$251,$A71,価格!$B$2:$B$251,"PC")) | Z71: =IF($A71="","",COUNTIFS(価格!$A$2:$A$251,$A71,価格!$B$2:$B$251,"オプション")) | AA71: =IF($A71="","",COUNTIFS(価格!$A$2:$A$251,$A71)-COUNTIFS(価格!$A$2:$A$251,$A71,価格!$H$2:$H$251,">0",価格!$J$2:$J$251,">0")) | AB71: =IF($A71="","",SUMIFS(価格!$N$2:$N$251,価格!$A$2:$A$251,$A71))

Sheet 価格
A1: 学校名 | B1: 種別 | C1: 品名 | D1: 昨年 掲載 | E1: 昨年 卸 | F1: 昨年 台数 | G1: 昨年 売上 | H1: 今年 掲載（エンド税別） | I1: 前年比 | J1: 今年 卸（税別） | K1: 手数料バック | L1: 手数料 単価 | M1: 見込 数量 | N1: 手数料 見込合計 | O1: 手数料率 | P1: 協力企業
A2: 青葉学園高等学校 | B2: PC | C2: Bモデル ノート13型 軽量 / i5・16GB | D2: 169000 | E2: 135000 | F2: 155 | G2: =IFERROR($D2*$F2,"") | H2: 172000 | I2: =IFERROR($H2/$D2-1,"") | J2: 140000 | K2: =IF($A2="","",IFERROR(INDEX(学校マスタ!$G$2:$G$71,MATCH($A2,学校マスタ!$A$2:$A$71,0)),"")) | L2: =IF(OR($A2="",$H2="",$J2=""),"",IF($K2="なし",0,$H2-$J2)) | M2: 160 | N2: =IFERROR($L2*$M2,"") | O2: =IFERROR($L2/$H2,"") | P2: =IF($A2="","",IFERROR(INDEX(学校マスタ!$F$2:$F$71,MATCH($A2,学校マスタ!$A$2:$A$71,0)),""))
A3: 青葉学園高等学校 | B3: PC | C3: Aモデル ノート14型 / i5・16GB | G3: =IFERROR($D3*$F3,"") | I3: =IFERROR($H3/$D3-1,"") | K3: =IF($A3="","",IFERROR(INDEX(学校マスタ!$G$2:$G$71,MATCH($A3,学校マスタ!$A$2:$A$71,0)),"")) | L3: =IF(OR($A3="",$H3="",$J3=""),"",IF($K3="なし",0,$H3-$J3)) | M3: 120 | N3: =IFERROR($L3*$M3,"") | O3: =IFERROR($L3/$H3,"") | P3: =IF($A3="","",IFERROR(INDEX(学校マスタ!$F$2:$F$71,MATCH($A3,学校マスタ!$A$2:$A$71,0)),""))
A4: 青葉学園高等学校 | B4: オプション | C4: キャリングケース | D4: 4800 | E4: 3200 | G4: =IFERROR($D4*$F4,"") | H4: 4800 | I4: =IFERROR($H4/$D4-1,"") | J4: 3200 | K4: =IF($A4="","",IFERROR(INDEX(学校マスタ!$G$2:$G$71,MATCH($A4,学校マスタ!$A$2:$A$71,0)),"")) | L4: =IF(OR($A4="",$H4="",$J4=""),"",IF($K4="なし",0,$H4-$J4)) | M4: 101 | N4: =IFERROR($L4*$M4,"") | O4: =IFERROR($L4/$H4,"") | P4: =IF($A4="","",IFERROR(INDEX(学校マスタ!$F$2:$F$71,MATCH($A4,学校マスタ!$A$2:$A$71,0)),""))
A5: 青葉学園高等学校 | B5: オプション | C5: Office 永続ライセンス | D5: 32000 | G5: =IFERROR($D5*$F5,"") | H5: 32000 | I5: =IFERROR($H5/$D5-1,"") | J5: 24000 | K5: =IF($A5="","",IFERROR(INDEX(学校マスタ!$G$2:$G$71,MATCH($A5,学校マスタ!$A$2:$A$71,0)),"")) | L5: =IF(OR($A5="",$H5="",$J5=""),"",IF($K5="なし",0,$H5-$J5)) | M5: 121 | N5: =IFERROR($L5*$M5,"") | O5: =IFERROR($L5/$H5,"") | P5: =IF($A5="","",IFERROR(INDEX(学校マスタ!$F$2:$F$71,MATCH($A5,学校マスタ!$A$2:$A$71,0)),""))
G6: =IFERROR($D6*$F6,"") | I6: =IFERROR($H6/$D6-1,"") | K6: =IF($A6="","",IFERROR(INDEX(学校マスタ!$G$2:$G$71,MATCH($A6,学校マスタ!$A$2:$A$71,0)),"")) | L6: =IF(OR($A6="",$H6="",$J6=""),"",IF($K6="なし",0,$H6-$J6)) | N6: =IFERROR($L6*$M6,"") | O6: =IFERROR($L6/$H6,"") | P6: =IF($A6="","",IFERROR(INDEX(学校マスタ!$F$2:$F$71,MATCH($A6,学校マスタ!$A$2:$A$71,0)),""))
G7: =IFERROR($D7*$F7,"") | I7: =IFERROR($H7/$D7-1,"") | K7: =IF($A7="","",IFERROR(INDEX(学校マスタ!$G$2:$G$71,MATCH($A7,学校マスタ!$A$2:$A$71,0)),"")) | L7: =IF(OR($A7="",$H7="",$J7=""),"",IF($K7="なし",0,$H7-$J7)) | N7: =IFERROR($L7*$M7,"") | O7: =IFERROR($L7/$H7,"") | P7: =IF($A7="","",IFERROR(INDEX(学校マスタ!$F$2:$F$71,MATCH($A7,学校マスタ!$A$2:$A$71,0)),""))
G8: =IFERROR($D8*$F8,"") | I8: =IFERROR($H8/$D8-1,"") | K8: =IF($A8="","",IFERROR(INDEX(学校マスタ!$G$2:$G$71,MATCH($A8,学校マスタ!$A$2:$A$71,0)),"")) | L8: =IF(OR($A8="",$H8="",$J8=""),"",IF($K8="なし",0,$H8-$J8)) | N8: =IFERROR($L8*$M8,"") | O8: =IFERROR($L8/$H8,"") | P8: =IF($A8="","",IFERROR(INDEX(学校マスタ!$F$2:$F$71,MATCH($A8,学校マスタ!$A$2:$A$71,0)),""))
G9: =IFERROR($D9*$F9,"") | I9: =IFERROR($H9/$D9-1,"") | K9: =IF($A9="","",IFERROR(INDEX(学校マスタ!$G$2:$G$71,MATCH($A9,学校マスタ!$A$2:$A$71,0)),"")) | L9: =IF(OR($A9="",$H9="",$J9=""),"",IF($K9="なし",0,$H9-$J9)) | N9: =IFERROR($L9*$M9,"") | O9: =IFERROR($L9/$H9,"") | P9: =IF($A9="","",IFERROR(INDEX(学校マスタ!$F$2:$F$71,MATCH($A9,学校マスタ!$A$2:$A$71,0)),""))
G10: =IFERROR($D10*$F10,"") | I10: =IFERROR($H10/$D10-1,"") | K10: =IF($A10="","",IFERROR(INDEX(学校マスタ!$G$2:$G$71,MATCH($A10,学校マスタ!$A$2:$A$71,0)),"")) | L10: =IF(OR($A10="",$H10="",$J10=""),"",IF($K10="なし",0,$H10-$J10)) | N10: =IFERROR($L10*$M10,"") | O10: =IFERROR($L10/$H10,"") | P10: =IF($A10="","",IFERROR(INDEX(学校マスタ!$F$2:$F$71,MATCH($A10,学校マスタ!$A$2:$A$71,0)),""))
G11: =IFERROR($D11*$F11,"") | I11: =IFERROR($H11/$D11-1,"") | K11: =IF($A11="","",IFERROR(INDEX(学校マスタ!$G$2:$G$71,MATCH($A11,学校マスタ!$A$2:$A$71,0)),"")) | L11: =IF(OR($A11="",$H11="",$J11=""),"",IF($K11="なし",0,$H11-$J11)) | N11: =IFERROR($L11*$M11,"") | O11: =IFERROR($L11/$H11,"") | P11: =IF($A11="","",IFERROR(INDEX(学校マスタ!$F$2:$F$71,MATCH($A11,学校マスタ!$A$2:$A$71,0)),""))
G12: =IFERROR($D12*$F12,"") | I12: =IFERROR($H12/$D12-1,"") | K12: =IF($A12="","",IFERROR(INDEX(学校マスタ!$G$2:$G$71,MATCH($A12,学校マスタ!$A$2:$A$71,0)),"")) | L12: =IF(OR($A12="",$H12="",$J12=""),"",IF($K12="なし",0,$H12-$J12)) | N12: =IFERROR($L12*$M12,"") | O12: =IFERROR($L12/$H12,"") | P12: =IF($A12="","",IFERROR(INDEX(学校マスタ!$F$2:$F$71,MATCH($A12,学校マスタ!$A$2:$A$71,0)),""))
G13: =IFERROR($D13*$F13,"") | I13: =IFERROR($H13/$D13-1,"") | K13: =IF($A13="","",IFERROR(INDEX(学校マスタ!$G$2:$G$71,MATCH($A13,学校マスタ!$A$2:$A$71,0)),"")) | L13: =IF(OR($A13="",$H13="",$J13=""),"",IF($K13="なし",0,$H13-$J13)) | N13: =IFERROR($L13*$M13,"") | O13: =IFERROR($L13/$H13,"") | P13: =IF($A13="","",IFERROR(INDEX(学校マスタ!$F$2:$F$71,MATCH($A13,学校マスタ!$A$2:$A$71,0)),""))
G14: =IFERROR($D14*$F14,"") | I14: =IFERROR($H14/$D14-1,"") | K14: =IF($A14="","",IFERROR(INDEX(学校マスタ!$G$2:$G$71,MATCH($A14,学校マスタ!$A$2:$A$71,0)),"")) | L14: =IF(OR($A14="",$H14="",$J14=""),"",IF($K14="なし",0,$H14-$J14)) | N14: =IFERROR($L14*$M14,"") | O14: =IFERROR($L14/$H14,"") | P14: =IF($A14="","",IFERROR(INDEX(学校マスタ!$F$2:$F$71,MATCH($A14,学校マスタ!$A$2:$A$71,0)),""))
G15: =IFERROR($D15*$F15,"") | I15: =IFERROR($H15/$D15-1,"") | K15: =IF($A15="","",IFERROR(INDEX(学校マスタ!$G$2:$G$71,MATCH($A15,学校マスタ!$A$2:$A$71,0)),"")) | L15: =IF(OR($A15="",$H15="",$J15=""),"",IF($K15="なし",0,$H15-$J15)) | N15: =IFERROR($L15*$M15,"") | O15: =IFERROR($L15/$H15,"") | P15: =IF($A15="","",IFERROR(INDEX(学校マスタ!$F$2:$F$71,MATCH($A15,学校マスタ!$A$2:$A$71,0)),""))
G16: =IFERROR($D16*$F16,"") | I16: =IFERROR($H16/$D16-1,"") | K16: =IF($A16="","",IFERROR(INDEX(学校マスタ!$G$2:$G$71,MATCH($A16,学校マスタ!$A$2:$A$71,0)),"")) | L16: =IF(OR($A16="",$H16="",$J16=""),"",IF($K16="なし",0,$H16-$J16)) | N16: =IFERROR($L16*$M16,"") | O16: =IFERROR($L16/$H16,"") | P16: =IF($A16="","",IFERROR(INDEX(学校マスタ!$F$2:$F$71,MATCH($A16,学校マスタ!$A$2:$A$71,0)),""))
G17: =IFERROR($D17*$F17,"") | I17: =IFERROR($H17/$D17-1,"") | K17: =IF($A17="","",IFERROR(INDEX(学校マスタ!$G$2:$G$71,MATCH($A17,学校マスタ!$A$2:$A$71,0)),"")) | L17: =IF(OR($A17="",$H17="",$J17=""),"",IF($K17="なし",0,$H17-$J17)) | N17: =IFERROR($L17*$M17,"") | O17: =IFERROR($L17/$H17,"") | P17: =IF($A17="","",IFERROR(INDEX(学校マスタ!$F$2:$F$71,MATCH($A17,学校マスタ!$A$2:$A$71,0)),""))
... G251: =IFERROR($D251*$F251,"") | I251: =IFERROR($H251/$D251-1,"") | K251: =IF($A251="","",IFERROR(INDEX(学校マスタ!$G$2:$G$71,MATCH($A251,学校マスタ!$A$2:$A$71,0)),"")) | L251: =IF(OR($A251="",$H251="",$J251=""),"",IF($K251="なし",0,$H251-$J251)) | N251: =IFERROR($L251*$M251,"") | O251: =IFERROR($L251/$H251,"") | P251: =IF($A251="","",IFERROR(INDEX(学校マスタ!$F$2:$F$71,MATCH($A251,学校マスタ!$A$2:$A$71,0)),""))

Sheet ガント
A1: ガント（1列＝1週間） | E1: █ チラシ調整期間 ▒ 販売開始→納品 ◆ 機種提示・意向回収・EC公開 ◎ 納品期日 （今週の列は色が付きます）
A2: 開始日 | B2: 46209 | C2: ←月曜日を入れてください
A3: 学校名 | B3: 担当 | C3: 状態 | D3: 販売開始 | E3: =$B$2 | F3: =E3+7 | G3: =F3+7 | H3: =G3+7 | I3: =H3+7 | J3: =I3+7 | K3: =J3+7 | L3: =K3+7 | M3: =L3+7 | ... AB3: =AA3+7
A4: =IF(学校マスタ!$A2="","",学校マスタ!$A2) | B4: =IF(学校マスタ!$A2="","",学校マスタ!$C2) | C4: =IF(学校マスタ!$A2="","",学校マスタ!$X2) | D4: =IF(学校マスタ!$A2="","",学校マスタ!$R2) | E4: =IF(学校マスタ!$A2="","",IF(AND(学校マスタ!$U2<>"",学校マスタ!$U2>=E$3,学校マスタ!$U2<E$3+7),"◎",IF(OR(AND(学校マスタ!$H2<>"",学校マスタ!$H2>=E$3,学校マスタ!$H2<E$3+7),AND(学校マスタ!$J2<>"",学校マスタ!$J2>=E$3,学校マスタ!$J2<E$3+7),AND(学校マスタ!$L2<>"",学校マスタ!$L2>=E$3,学校マスタ!$L2<E$3+7)),"◆",IF(AND(学校マスタ!$O2<>"",学校マスタ!$P2<>"",学校マスタ!$O2<E$3+7,学校マスタ!$P2>=E$3),"█",IF(AND(学校マスタ!$R2<>"",学校マスタ!$U2<>"",学校マスタ!$R2<E$3+7,学校マスタ!$U2>=E$3),"▒",""))))) | F4: =IF(学校マスタ!$A2="","",IF(AND(学校マスタ!$U2<>"",学校マスタ!$U2>=F$3,学校マスタ!$U2<F$3+7),"◎",IF(OR(AND(学校マスタ!$H2<>"",学校マスタ!$H2>=F$3,学校マスタ!$H2<F$3+7),AND(学校マスタ!$J2<>"",学校マスタ!$J2>=F$3,学校マスタ!$J2<F$3+7),AND(学校マスタ!$L2<>"",学校マスタ!$L2>=F$3,学校マスタ!$L2<F$3+7)),"◆",IF(AND(学校マスタ!$O2<>"",学校マスタ!$P2<>"",学校マスタ!$O2<F$3+7,学校マスタ!$P2>=F$3),"█",IF(AND(学校マスタ!$R2<>"",学校マスタ!$U2<>"",学校マスタ!$R2<F$3+7,学校マスタ!$U2>=F$3),"▒",""))))) | G4: =IF(学校マスタ!$A2="","",IF(AND(学校マスタ!$U2<>"",学校マスタ!$U2>=G$3,学校マスタ!$U2<G$3+7),"◎",IF(OR(AND(学校マスタ!$H2<>"",学校マスタ!$H2>=G$3,学校マスタ!$H2<G$3+7),AND(学校マスタ!$J2<>"",学校マスタ!$J2>=G$3,学校マスタ!$J2<G$3+7),AND(学校マスタ!$L2<>"",学校マスタ!$L2>=G$3,学校マスタ!$L2<G$3+7)),"◆",IF(AND(学校マスタ!$O2<>"",学校マスタ!$P2<>"",学校マスタ!$O2<G$3+7,学校マスタ!$P2>=G$3),"█",IF(AND(学校マスタ!$R2<>"",学校マスタ!$U2<>"",学校マスタ!$R2<G$3+7,学校マスタ!$U2>=G$3),"▒",""))))) | H4: =IF(学校マスタ!$A2="","",IF(AND(学校マスタ!$U2<>"",学校マスタ!$U2>=H$3,学校マスタ!$U2<H$3+7),"◎",IF(OR(AND(学校マスタ!$H2<>"",学校マスタ!$H2>=H$3,学校マスタ!$H2<H$3+7),AND(学校マスタ!$J2<>"",学校マスタ!$J2>=H$3,学校マスタ!$J2<H$3+7),AND(学校マスタ!$L2<>"",学校マスタ!$L2>=H$3,学校マスタ!$L2<H$3+7)),"◆",IF(AND(学校マスタ!$O2<>"",学校マスタ!$P2<>"",学校マスタ!$O2<H$3+7,学校マスタ!$P2>=H$3),"█",IF(AND(学校マスタ!$R2<>"",学校マスタ!$U2<>"",学校マスタ!$R2<H$3+7,学校マスタ!$U2>=H$3),"▒",""))))) | I4: =IF(学校マスタ!$A2="","",IF(AND(学校マスタ!$U2<>"",学校マスタ!$U2>=I$3,学校マスタ!$U2<I$3+7),"◎",IF(OR(AND(学校マスタ!$H2<>"",学校マスタ!$H2>=I$3,学校マスタ!$H2<I$3+7),AND(学校マスタ!$J2<>"",学校マスタ!$J2>=I$3,学校マスタ!$J2<I$3+7),AND(学校マスタ!$L2<>"",学校マスタ!$L2>=I$3,学校マスタ!$L2<I$3+7)),"◆",IF(AND(学校マスタ!$O2<>"",学校マスタ!$P2<>"",学校マスタ!$O2<I$3+7,学校マスタ!$P2>=I$3),"█",IF(AND(学校マスタ!$R2<>"",学校マスタ!$U2<>"",学校マスタ!$R2<I$3+7,学校マスタ!$U2>=I$3),"▒",""))))) | J4: =IF(学校マスタ!$A2="","",IF(AND(学校マスタ!$U2<>"",学校マスタ!$U2>=J$3,学校マスタ!$U2<J$3+7),"◎",IF(OR(AND(学校マスタ!$H2<>"",学校マスタ!$H2>=J$3,学校マスタ!$H2<J$3+7),AND(学校マスタ!$J2<>"",学校マスタ!$J2>=J$3,学校マスタ!$J2<J$3+7),AND(学校マスタ!$L2<>"",学校マスタ!$L2>=J$3,学校マスタ!$L2<J$3+7)),"◆",IF(AND(学校マスタ!$O2<>"",学校マスタ!$P2<>"",学校マスタ!$O2<J$3+7,学校マスタ!$P2>=J$3),"█",IF(AND(学校マスタ!$R2<>"",学校マスタ!$U2<>"",学校マスタ!$R2<J$3+7,学校マスタ!$U2>=J$3),"▒",""))))) | K4: =IF(学校マスタ!$A2="","",IF(AND(学校マスタ!$U2<>"",学校マスタ!$U2>=K$3,学校マスタ!$U2<K$3+7),"◎",IF(OR(AND(学校マスタ!$H2<>"",学校マスタ!$H2>=K$3,学校マスタ!$H2<K$3+7),AND(学校マスタ!$J2<>"",学校マスタ!$J2>=K$3,学校マスタ!$J2<K$3+7),AND(学校マスタ!$L2<>"",学校マスタ!$L2>=K$3,学校マスタ!$L2<K$3+7)),"◆",IF(AND(学校マスタ!$O2<>"",学校マスタ!$P2<>"",学校マスタ!$O2<K$3+7,学校マスタ!$P2>=K$3),"█",IF(AND(学校マスタ!$R2<>"",学校マスタ!$U2<>"",学校マスタ!$R2<K$3+7,学校マスタ!$U2>=K$3),"▒",""))))) | L4: =IF(学校マスタ!$A2="","",IF(AND(学校マスタ!$U2<>"",学校マスタ!$U2>=L$3,学校マスタ!$U2<L$3+7),"◎",IF(OR(AND(学校マスタ!$H2<>"",学校マスタ!$H2>=L$3,学校マスタ!$H2<L$3+7),AND(学校マスタ!$J2<>"",学校マスタ!$J2>=L$3,学校マスタ!$J2<L$3+7),AND(学校マスタ!$L2<>"",学校マスタ!$L2>=L$3,学校マスタ!$L2<L$3+7)),"◆",IF(AND(学校マスタ!$O2<>"",学校マスタ!$P2<>"",学校マスタ!$O2<L$3+7,学校マスタ!$P2>=L$3),"█",IF(AND(学校マスタ!$R2<>"",学校マスタ!$U2<>"",学校マスタ!$R2<L$3+7,学校マスタ!$U2>=L$3),"▒",""))))) | ... AB4: =IF(学校マスタ!$A2="","",IF(AND(学校マスタ!$U2<>"",学校マスタ!$U2>=AB$3,学校マスタ!$U2<AB$3+7),"◎",IF(OR(AND(学校マスタ!$H2<>"",学校マスタ!$H2>=AB$3,学校マスタ!$H2<AB$3+7),AND(学校マスタ!$J2<>"",学校マスタ!$J2>=AB$3,学校マスタ!$J2<AB$3+7),AND(学校マスタ!$L2<>"",学校マスタ!$L2>=AB$3,学校マスタ!$L2<AB$3+7)),"◆",IF(AND(学校マスタ!$O2<>"",学校マスタ!$P2<>"",学校マスタ!$O2<AB$3+7,学校マスタ!$P2>=AB$3),"█",IF(AND(学校マスタ!$R2<>"",学校マスタ!$U2<>"",学校マスタ!$R2<AB$3+7,学校マスタ!$U2>=AB$3),"▒","")))))
A5: =IF(学校マスタ!$A3="","",学校マスタ!$A3) | B5: =IF(学校マスタ!$A3="","",学校マスタ!$C3) | C5: =IF(学校マスタ!$A3="","",学校マスタ!$X3) | D5: =IF(学校マスタ!$A3="","",学校マスタ!$R3) | E5: =IF(学校マスタ!$A3="","",IF(AND(学校マスタ!$U3<>"",学校マスタ!$U3>=E$3,学校マスタ!$U3<E$3+7),"◎",IF(OR(AND(学校マスタ!$H3<>"",学校マスタ!$H3>=E$3,学校マスタ!$H3<E$3+7),AND(学校マスタ!$J3<>"",学校マスタ!$J3>=E$3,学校マスタ!$J3<E$3+7),AND(学校マスタ!$L3<>"",学校マスタ!$L3>=E$3,学校マスタ!$L3<E$3+7)),"◆",IF(AND(学校マスタ!$O3<>"",学校マスタ!$P3<>"",学校マスタ!$O3<E$3+7,学校マスタ!$P3>=E$3),"█",IF(AND(学校マスタ!$R3<>"",学校マスタ!$U3<>"",学校マスタ!$R3<E$3+7,学校マスタ!$U3>=E$3),"▒",""))))) | F5: =IF(学校マスタ!$A3="","",IF(AND(学校マスタ!$U3<>"",学校マスタ!$U3>=F$3,学校マスタ!$U3<F$3+7),"◎",IF(OR(AND(学校マスタ!$H3<>"",学校マスタ!$H3>=F$3,学校マスタ!$H3<F$3+7),AND(学校マスタ!$J3<>"",学校マスタ!$J3>=F$3,学校マスタ!$J3<F$3+7),AND(学校マスタ!$L3<>"",学校マスタ!$L3>=F$3,学校マスタ!$L3<F$3+7)),"◆",IF(AND(学校マスタ!$O3<>"",学校マスタ!$P3<>"",学校マスタ!$O3<F$3+7,学校マスタ!$P3>=F$3),"█",IF(AND(学校マスタ!$R3<>"",学校マスタ!$U3<>"",学校マスタ!$R3<F$3+7,学校マスタ!$U3>=F$3),"▒",""))))) | G5: =IF(学校マスタ!$A3="","",IF(AND(学校マスタ!$U3<>"",学校マスタ!$U3>=G$3,学校マスタ!$U3<G$3+7),"◎",IF(OR(AND(学校マスタ!$H3<>"",学校マスタ!$H3>=G$3,学校マスタ!$H3<G$3+7),AND(学校マスタ!$J3<>"",学校マスタ!$J3>=G$3,学校マスタ!$J3<G$3+7),AND(学校マスタ!$L3<>"",学校マスタ!$L3>=G$3,学校マスタ!$L3<G$3+7)),"◆",IF(AND(学校マスタ!$O3<>"",学校マスタ!$P3<>"",学校マスタ!$O3<G$3+7,学校マスタ!$P3>=G$3),"█",IF(AND(学校マスタ!$R3<>"",学校マスタ!$U3<>"",学校マスタ!$R3<G$3+7,学校マスタ!$U3>=G$3),"▒",""))))) | H5: =IF(学校マスタ!$A3="","",IF(AND(学校マスタ!$U3<>"",学校マスタ!$U3>=H$3,学校マスタ!$U3<H$3+7),"◎",IF(OR(AND(学校マスタ!$H3<>"",学校マスタ!$H3>=H$3,学校マスタ!$H3<H$3+7),AND(学校マスタ!$J3<>"",学校マスタ!$J3>=H$3,学校マスタ!$J3<H$3+7),AND(学校マスタ!$L3<>"",学校マスタ!$L3>=H$3,学校マスタ!$L3<H$3+7)),"◆",IF(AND(学校マスタ!$O3<>"",学校マスタ!$P3<>"",学校マスタ!$O3<H$3+7,学校マスタ!$P3>=H$3),"█",IF(AND(学校マスタ!$R3<>"",学校マスタ!$U3<>"",学校マスタ!$R3<H$3+7,学校マスタ!$U3>=H$3),"▒",""))))) | I5: =IF(学校マスタ!$A3="","",IF(AND(学校マスタ!$U3<>"",学校マスタ!$U3>=I$3,学校マスタ!$U3<I$3+7),"◎",IF(OR(AND(学校マスタ!$H3<>"",学校マスタ!$H3>=I$3,学校マスタ!$H3<I$3+7),AND(学校マスタ!$J3<>"",学校マスタ!$J3>=I$3,学校マスタ!$J3<I$3+7),AND(学校マスタ!$L3<>"",学校マスタ!$L3>=I$3,学校マスタ!$L3<I$3+7)),"◆",IF(AND(学校マスタ!$O3<>"",学校マスタ!$P3<>"",学校マスタ!$O3<I$3+7,学校マスタ!$P3>=I$3),"█",IF(AND(学校マスタ!$R3<>"",学校マスタ!$U3<>"",学校マスタ!$R3<I$3+7,学校マスタ!$U3>=I$3),"▒",""))))) | J5: =IF(学校マスタ!$A3="","",IF(AND(学校マスタ!$U3<>"",学校マスタ!$U3>=J$3,学校マスタ!$U3<J$3+7),"◎",IF(OR(AND(学校マスタ!$H3<>"",学校マスタ!$H3>=J$3,学校マスタ!$H3<J$3+7),AND(学校マスタ!$J3<>"",学校マスタ!$J3>=J$3,学校マスタ!$J3<J$3+7),AND(学校マスタ!$L3<>"",学校マスタ!$L3>=J$3,学校マスタ!$L3<J$3+7)),"◆",IF(AND(学校マスタ!$O3<>"",学校マスタ!$P3<>"",学校マスタ!$O3<J$3+7,学校マスタ!$P3>=J$3),"█",IF(AND(学校マスタ!$R3<>"",学校マスタ!$U3<>"",学校マスタ!$R3<J$3+7,学校マスタ!$U3>=J$3),"▒",""))))) | K5: =IF(学校マスタ!$A3="","",IF(AND(学校マスタ!$U3<>"",学校マスタ!$U3>=K$3,学校マスタ!$U3<K$3+7),"◎",IF(OR(AND(学校マスタ!$H3<>"",学校マスタ!$H3>=K$3,学校マスタ!$H3<K$3+7),AND(学校マスタ!$J3<>"",学校マスタ!$J3>=K$3,学校マスタ!$J3<K$3+7),AND(学校マスタ!$L3<>"",学校マスタ!$L3>=K$3,学校マスタ!$L3<K$3+7)),"◆",IF(AND(学校マスタ!$O3<>"",学校マスタ!$P3<>"",学校マスタ!$O3<K$3+7,学校マスタ!$P3>=K$3),"█",IF(AND(学校マスタ!$R3<>"",学校マスタ!$U3<>"",学校マスタ!$R3<K$3+7,学校マスタ!$U3>=K$3),"▒",""))))) | L5: =IF(学校マスタ!$A3="","",IF(AND(学校マスタ!$U3<>"",学校マスタ!$U3>=L$3,学校マスタ!$U3<L$3+7),"◎",IF(OR(AND(学校マスタ!$H3<>"",学校マスタ!$H3>=L$3,学校マスタ!$H3<L$3+7),AND(学校マスタ!$J3<>"",学校マスタ!$J3>=L$3,学校マスタ!$J3<L$3+7),AND(学校マスタ!$L3<>"",学校マスタ!$L3>=L$3,学校マスタ!$L3<L$3+7)),"◆",IF(AND(学校マスタ!$O3<>"",学校マスタ!$P3<>"",学校マスタ!$O3<L$3+7,学校マスタ!$P3>=L$3),"█",IF(AND(学校マスタ!$R3<>"",学校マスタ!$U3<>"",学校マスタ!$R3<L$3+7,学校マスタ!$U3>=L$3),"▒",""))))) | ... AB5: =IF(学校マスタ!$A3="","",IF(AND(学校マスタ!$U3<>"",学校マスタ!$U3>=AB$3,学校マスタ!$U3<AB$3+7),"◎",IF(OR(AND(学校マスタ!$H3<>"",学校マスタ!$H3>=AB$3,学校マスタ!$H3<AB$3+7),AND(学校マスタ!$J3<>"",学校マスタ!$J3>=AB$3,学校マスタ!$J3<AB$3+7),AND(学校マスタ!$L3<>"",学校マスタ!$L3>=AB$3,学校マスタ!$L3<AB$3+7)),"◆",IF(AND(学校マスタ!$O3<>"",学校マスタ!$P3<>"",学校マスタ!$O3<AB$3+7,学校マスタ!$P3>=AB$3),"█",IF(AND(学校マスタ!$R3<>"",学校マスタ!$U3<>"",学校マスタ!$R3<AB$3+7,学校マスタ!$U3>=AB$3),"▒","")))))
A6: =IF(学校マスタ!$A4="","",学校マスタ!$A4) | B6: =IF(学校マスタ!$A4="","",学校マスタ!$C4) | C6: =IF(学校マスタ!$A4="","",学校マスタ!$X4) | D6: =IF(学校マスタ!$A4="","",学校マスタ!$R4) | E6: =IF(学校マスタ!$A4="","",IF(AND(学校マスタ!$U4<>"",学校マスタ!$U4>=E$3,学校マスタ!$U4<E$3+7),"◎",IF(OR(AND(学校マスタ!$H4<>"",学校マスタ!$H4>=E$3,学校マスタ!$H4<E$3+7),AND(学校マスタ!$J4<>"",学校マスタ!$J4>=E$3,学校マスタ!$J4<E$3+7),AND(学校マスタ!$L4<>"",学校マスタ!$L4>=E$3,学校マスタ!$L4<E$3+7)),"◆",IF(AND(学校マスタ!$O4<>"",学校マスタ!$P4<>"",学校マスタ!$O4<E$3+7,学校マスタ!$P4>=E$3),"█",IF(AND(学校マスタ!$R4<>"",学校マスタ!$U4<>"",学校マスタ!$R4<E$3+7,学校マスタ!$U4>=E$3),"▒",""))))) | F6: =IF(学校マスタ!$A4="","",IF(AND(学校マスタ!$U4<>"",学校マスタ!$U4>=F$3,学校マスタ!$U4<F$3+7),"◎",IF(OR(AND(学校マスタ!$H4<>"",学校マスタ!$H4>=F$3,学校マスタ!$H4<F$3+7),AND(学校マスタ!$J4<>"",学校マスタ!$J4>=F$3,学校マスタ!$J4<F$3+7),AND(学校マスタ!$L4<>"",学校マスタ!$L4>=F$3,学校マスタ!$L4<F$3+7)),"◆",IF(AND(学校マスタ!$O4<>"",学校マスタ!$P4<>"",学校マスタ!$O4<F$3+7,学校マスタ!$P4>=F$3),"█",IF(AND(学校マスタ!$R4<>"",学校マスタ!$U4<>"",学校マスタ!$R4<F$3+7,学校マスタ!$U4>=F$3),"▒",""))))) | G6: =IF(学校マスタ!$A4="","",IF(AND(学校マスタ!$U4<>"",学校マスタ!$U4>=G$3,学校マスタ!$U4<G$3+7),"◎",IF(OR(AND(学校マスタ!$H4<>"",学校マスタ!$H4>=G$3,学校マスタ!$H4<G$3+7),AND(学校マスタ!$J4<>"",学校マスタ!$J4>=G$3,学校マスタ!$J4<G$3+7),AND(学校マスタ!$L4<>"",学校マスタ!$L4>=G$3,学校マスタ!$L4<G$3+7)),"◆",IF(AND(学校マスタ!$O4<>"",学校マスタ!$P4<>"",学校マスタ!$O4<G$3+7,学校マスタ!$P4>=G$3),"█",IF(AND(学校マスタ!$R4<>"",学校マスタ!$U4<>"",学校マスタ!$R4<G$3+7,学校マスタ!$U4>=G$3),"▒",""))))) | H6: =IF(学校マスタ!$A4="","",IF(AND(学校マスタ!$U4<>"",学校マスタ!$U4>=H$3,学校マスタ!$U4<H$3+7),"◎",IF(OR(AND(学校マスタ!$H4<>"",学校マスタ!$H4>=H$3,学校マスタ!$H4<H$3+7),AND(学校マスタ!$J4<>"",学校マスタ!$J4>=H$3,学校マスタ!$J4<H$3+7),AND(学校マスタ!$L4<>"",学校マスタ!$L4>=H$3,学校マスタ!$L4<H$3+7)),"◆",IF(AND(学校マスタ!$O4<>"",学校マスタ!$P4<>"",学校マスタ!$O4<H$3+7,学校マスタ!$P4>=H$3),"█",IF(AND(学校マスタ!$R4<>"",学校マスタ!$U4<>"",学校マスタ!$R4<H$3+7,学校マスタ!$U4>=H$3),"▒",""))))) | I6: =IF(学校マスタ!$A4="","",IF(AND(学校マスタ!$U4<>"",学校マスタ!$U4>=I$3,学校マスタ!$U4<I$3+7),"◎",IF(OR(AND(学校マスタ!$H4<>"",学校マスタ!$H4>=I$3,学校マスタ!$H4<I$3+7),AND(学校マスタ!$J4<>"",学校マスタ!$J4>=I$3,学校マスタ!$J4<I$3+7),AND(学校マスタ!$L4<>"",学校マスタ!$L4>=I$3,学校マスタ!$L4<I$3+7)),"◆",IF(AND(学校マスタ!$O4<>"",学校マスタ!$P4<>"",学校マスタ!$O4<I$3+7,学校マスタ!$P4>=I$3),"█",IF(AND(学校マスタ!$R4<>"",学校マスタ!$U4<>"",学校マスタ!$R4<I$3+7,学校マスタ!$U4>=I$3),"▒",""))))) | J6: =IF(学校マスタ!$A4="","",IF(AND(学校マスタ!$U4<>"",学校マスタ!$U4>=J$3,学校マスタ!$U4<J$3+7),"◎",IF(OR(AND(学校マスタ!$H4<>"",学校マスタ!$H4>=J$3,学校マスタ!$H4<J$3+7),AND(学校マスタ!$J4<>"",学校マスタ!$J4>=J$3,学校マスタ!$J4<J$3+7),AND(学校マスタ!$L4<>"",学校マスタ!$L4>=J$3,学校マスタ!$L4<J$3+7)),"◆",IF(AND(学校マスタ!$O4<>"",学校マスタ!$P4<>"",学校マスタ!$O4<J$3+7,学校マスタ!$P4>=J$3),"█",IF(AND(学校マスタ!$R4<>"",学校マスタ!$U4<>"",学校マスタ!$R4<J$3+7,学校マスタ!$U4>=J$3),"▒",""))))) | K6: =IF(学校マスタ!$A4="","",IF(AND(学校マスタ!$U4<>"",学校マスタ!$U4>=K$3,学校マスタ!$U4<K$3+7),"◎",IF(OR(AND(学校マスタ!$H4<>"",学校マスタ!$H4>=K$3,学校マスタ!$H4<K$3+7),AND(学校マスタ!$J4<>"",学校マスタ!$J4>=K$3,学校マスタ!$J4<K$3+7),AND(学校マスタ!$L4<>"",学校マスタ!$L4>=K$3,学校マスタ!$L4<K$3+7)),"◆",IF(AND(学校マスタ!$O4<>"",学校マスタ!$P4<>"",学校マスタ!$O4<K$3+7,学校マスタ!$P4>=K$3),"█",IF(AND(学校マスタ!$R4<>"",学校マスタ!$U4<>"",学校マスタ!$R4<K$3+7,学校マスタ!$U4>=K$3),"▒",""))))) | L6: =IF(学校マスタ!$A4="","",IF(AND(学校マスタ!$U4<>"",学校マスタ!$U4>=L$3,学校マスタ!$U4<L$3+7),"◎",IF(OR(AND(学校マスタ!$H4<>"",学校マスタ!$H4>=L$3,学校マスタ!$H4<L$3+7),AND(学校マスタ!$J4<>"",学校マスタ!$J4>=L$3,学校マスタ!$J4<L$3+7),AND(学校マスタ!$L4<>"",学校マスタ!$L4>=L$3,学校マスタ!$L4<L$3+7)),"◆",IF(AND(学校マスタ!$O4<>"",学校マスタ!$P4<>"",学校マスタ!$O4<L$3+7,学校マスタ!$P4>=L$3),"█",IF(AND(学校マスタ!$R4<>"",学校マスタ!$U4<>"",学校マスタ!$R4<L$3+7,学校マスタ!$U4>=L$3),"▒",""))))) | ... AB6: =IF(学校マスタ!$A4="","",IF(AND(学校マスタ!$U4<>"",学校マスタ!$U4>=AB$3,学校マスタ!$U4<AB$3+7),"◎",IF(OR(AND(学校マスタ!$H4<>"",学校マスタ!$H4>=AB$3,学校マスタ!$H4<AB$3+7),AND(学校マスタ!$J4<>"",学校マスタ!$J4>=AB$3,学校マスタ!$J4<AB$3+7),AND(学校マスタ!$L4<>"",学校マスタ!$L4>=AB$3,学校マスタ!$L4<AB$3+7)),"◆",IF(AND(学校マスタ!$O4<>"",学校マスタ!$P4<>"",学校マスタ!$O4<AB$3+7,学校マスタ!$P4>=AB$3),"█",IF(AND(学校マスタ!$R4<>"",学校マスタ!$U4<>"",学校マスタ!$R4<AB$3+7,学校マスタ!$U4>=AB$3),"▒","")))))
A7: =IF(学校マスタ!$A5="","",学校マスタ!$A5) | B7: =IF(学校マスタ!$A5="","",学校マスタ!$C5) | C7: =IF(学校マスタ!$A5="","",学校マスタ!$X5) | D7: =IF(学校マスタ!$A5="","",学校マスタ!$R5) | E7: =IF(学校マスタ!$A5="","",IF(AND(学校マスタ!$U5<>"",学校マスタ!$U5>=E$3,学校マスタ!$U5<E$3+7),"◎",IF(OR(AND(学校マスタ!$H5<>"",学校マスタ!$H5>=E$3,学校マスタ!$H5<E$3+7),AND(学校マスタ!$J5<>"",学校マスタ!$J5>=E$3,学校マスタ!$J5<E$3+7),AND(学校マスタ!$L5<>"",学校マスタ!$L5>=E$3,学校マスタ!$L5<E$3+7)),"◆",IF(AND(学校マスタ!$O5<>"",学校マスタ!$P5<>"",学校マスタ!$O5<E$3+7,学校マスタ!$P5>=E$3),"█",IF(AND(学校マスタ!$R5<>"",学校マスタ!$U5<>"",学校マスタ!$R5<E$3+7,学校マスタ!$U5>=E$3),"▒",""))))) | F7: =IF(学校マスタ!$A5="","",IF(AND(学校マスタ!$U5<>"",学校マスタ!$U5>=F$3,学校マスタ!$U5<F$3+7),"◎",IF(OR(AND(学校マスタ!$H5<>"",学校マスタ!$H5>=F$3,学校マスタ!$H5<F$3+7),AND(学校マスタ!$J5<>"",学校マスタ!$J5>=F$3,学校マスタ!$J5<F$3+7),AND(学校マスタ!$L5<>"",学校マスタ!$L5>=F$3,学校マスタ!$L5<F$3+7)),"◆",IF(AND(学校マスタ!$O5<>"",学校マスタ!$P5<>"",学校マスタ!$O5<F$3+7,学校マスタ!$P5>=F$3),"█",IF(AND(学校マスタ!$R5<>"",学校マスタ!$U5<>"",学校マスタ!$R5<F$3+7,学校マスタ!$U5>=F$3),"▒",""))))) | G7: =IF(学校マスタ!$A5="","",IF(AND(学校マスタ!$U5<>"",学校マスタ!$U5>=G$3,学校マスタ!$U5<G$3+7),"◎",IF(OR(AND(学校マスタ!$H5<>"",学校マスタ!$H5>=G$3,学校マスタ!$H5<G$3+7),AND(学校マスタ!$J5<>"",学校マスタ!$J5>=G$3,学校マスタ!$J5<G$3+7),AND(学校マスタ!$L5<>"",学校マスタ!$L5>=G$3,学校マスタ!$L5<G$3+7)),"◆",IF(AND(学校マスタ!$O5<>"",学校マスタ!$P5<>"",学校マスタ!$O5<G$3+7,学校マスタ!$P5>=G$3),"█",IF(AND(学校マスタ!$R5<>"",学校マスタ!$U5<>"",学校マスタ!$R5<G$3+7,学校マスタ!$U5>=G$3),"▒",""))))) | H7: =IF(学校マスタ!$A5="","",IF(AND(学校マスタ!$U5<>"",学校マスタ!$U5>=H$3,学校マスタ!$U5<H$3+7),"◎",IF(OR(AND(学校マスタ!$H5<>"",学校マスタ!$H5>=H$3,学校マスタ!$H5<H$3+7),AND(学校マスタ!$J5<>"",学校マスタ!$J5>=H$3,学校マスタ!$J5<H$3+7),AND(学校マスタ!$L5<>"",学校マスタ!$L5>=H$3,学校マスタ!$L5<H$3+7)),"◆",IF(AND(学校マスタ!$O5<>"",学校マスタ!$P5<>"",学校マスタ!$O5<H$3+7,学校マスタ!$P5>=H$3),"█",IF(AND(学校マスタ!$R5<>"",学校マスタ!$U5<>"",学校マスタ!$R5<H$3+7,学校マスタ!$U5>=H$3),"▒",""))))) | I7: =IF(学校マスタ!$A5="","",IF(AND(学校マスタ!$U5<>"",学校マスタ!$U5>=I$3,学校マスタ!$U5<I$3+7),"◎",IF(OR(AND(学校マスタ!$H5<>"",学校マスタ!$H5>=I$3,学校マスタ!$H5<I$3+7),AND(学校マスタ!$J5<>"",学校マスタ!$J5>=I$3,学校マスタ!$J5<I$3+7),AND(学校マスタ!$L5<>"",学校マスタ!$L5>=I$3,学校マスタ!$L5<I$3+7)),"◆",IF(AND(学校マスタ!$O5<>"",学校マスタ!$P5<>"",学校マスタ!$O5<I$3+7,学校マスタ!$P5>=I$3),"█",IF(AND(学校マスタ!$R5<>"",学校マスタ!$U5<>"",学校マスタ!$R5<I$3+7,学校マスタ!$U5>=I$3),"▒",""))))) | J7: =IF(学校マスタ!$A5="","",IF(AND(学校マスタ!$U5<>"",学校マスタ!$U5>=J$3,学校マスタ!$U5<J$3+7),"◎",IF(OR(AND(学校マスタ!$H5<>"",学校マスタ!$H5>=J$3,学校マスタ!$H5<J$3+7),AND(学校マスタ!$J5<>"",学校マスタ!$J5>=J$3,学校マスタ!$J5<J$3+7),AND(学校マスタ!$L5<>"",学校マスタ!$L5>=J$3,学校マスタ!$L5<J$3+7)),"◆",IF(AND(学校マスタ!$O5<>"",学校マスタ!$P5<>"",学校マスタ!$O5<J$3+7,学校マスタ!$P5>=J$3),"█",IF(AND(学校マスタ!$R5<>"",学校マスタ!$U5<>"",学校マスタ!$R5<J$3+7,学校マスタ!$U5>=J$3),"▒",""))))) | K7: =IF(学校マスタ!$A5="","",IF(AND(学校マスタ!$U5<>"",学校マスタ!$U5>=K$3,学校マスタ!$U5<K$3+7),"◎",IF(OR(AND(学校マスタ!$H5<>"",学校マスタ!$H5>=K$3,学校マスタ!$H5<K$3+7),AND(学校マスタ!$J5<>"",学校マスタ!$J5>=K$3,学校マスタ!$J5<K$3+7),AND(学校マスタ!$L5<>"",学校マスタ!$L5>=K$3,学校マスタ!$L5<K$3+7)),"◆",IF(AND(学校マスタ!$O5<>"",学校マスタ!$P5<>"",学校マスタ!$O5<K$3+7,学校マスタ!$P5>=K$3),"█",IF(AND(学校マスタ!$R5<>"",学校マスタ!$U5<>"",学校マスタ!$R5<K$3+7,学校マスタ!$U5>=K$3),"▒",""))))) | L7: =IF(学校マスタ!$A5="","",IF(AND(学校マスタ!$U5<>"",学校マスタ!$U5>=L$3,学校マスタ!$U5<L$3+7),"◎",IF(OR(AND(学校マスタ!$H5<>"",学校マスタ!$H5>=L$3,学校マスタ!$H5<L$3+7),AND(学校マスタ!$J5<>"",学校マスタ!$J5>=L$3,学校マスタ!$J5<L$3+7),AND(学校マスタ!$L5<>"",学校マスタ!$L5>=L$3,学校マスタ!$L5<L$3+7)),"◆",IF(AND(学校マスタ!$O5<>"",学校マスタ!$P5<>"",学校マスタ!$O5<L$3+7,学校マスタ!$P5>=L$3),"█",IF(AND(学校マスタ!$R5<>"",学校マスタ!$U5<>"",学校マスタ!$R5<L$3+7,学校マスタ!$U5>=L$3),"▒",""))))) | ... AB7: =IF(学校マスタ!$A5="","",IF(AND(学校マスタ!$U5<>"",学校マスタ!$U5>=AB$3,学校マスタ!$U5<AB$3+7),"◎",IF(OR(AND(学校マスタ!$H5<>"",学校マスタ!$H5>=AB$3,学校マスタ!$H5<AB$3+7),AND(学校マスタ!$J5<>"",学校マスタ!$J5>=AB$3,学校マスタ!$J5<AB$3+7),AND(学校マスタ!$L5<>"",学校マスタ!$L5>=AB$3,学校マスタ!$L5<AB$3+7)),"◆",IF(AND(学校マスタ!$O5<>"",学校マスタ!$P5<>"",学校マスタ!$O5<AB$3+7,学校マスタ!$P5>=AB$3),"█",IF(AND(学校マスタ!$R5<>"",学校マスタ!$U5<>"",学校マスタ!$R5<AB$3+7,学校マスタ!$U5>=AB$3),"▒","")))))
A8: =IF(学校マスタ!$A6="","",学校マスタ!$A6) | B8: =IF(学校マスタ!$A6="","",学校マスタ!$C6) | C8: =IF(学校マスタ!$A6="","",学校マスタ!$X6) | D8: =IF(学校マスタ!$A6="","",学校マスタ!$R6) | E8: =IF(学校マスタ!$A6="","",IF(AND(学校マスタ!$U6<>"",学校マスタ!$U6>=E$3,学校マスタ!$U6<E$3+7),"◎",IF(OR(AND(学校マスタ!$H6<>"",学校マスタ!$H6>=E$3,学校マスタ!$H6<E$3+7),AND(学校マスタ!$J6<>"",学校マスタ!$J6>=E$3,学校マスタ!$J6<E$3+7),AND(学校マスタ!$L6<>"",学校マスタ!$L6>=E$3,学校マスタ!$L6<E$3+7)),"◆",IF(AND(学校マスタ!$O6<>"",学校マスタ!$P6<>"",学校マスタ!$O6<E$3+7,学校マスタ!$P6>=E$3),"█",IF(AND(学校マスタ!$R6<>"",学校マスタ!$U6<>"",学校マスタ!$R6<E$3+7,学校マスタ!$U6>=E$3),"▒",""))))) | F8: =IF(学校マスタ!$A6="","",IF(AND(学校マスタ!$U6<>"",学校マスタ!$U6>=F$3,学校マスタ!$U6<F$3+7),"◎",IF(OR(AND(学校マスタ!$H6<>"",学校マスタ!$H6>=F$3,学校マスタ!$H6<F$3+7),AND(学校マスタ!$J6<>"",学校マスタ!$J6>=F$3,学校マスタ!$J6<F$3+7),AND(学校マスタ!$L6<>"",学校マスタ!$L6>=F$3,学校マスタ!$L6<F$3+7)),"◆",IF(AND(学校マスタ!$O6<>"",学校マスタ!$P6<>"",学校マスタ!$O6<F$3+7,学校マスタ!$P6>=F$3),"█",IF(AND(学校マスタ!$R6<>"",学校マスタ!$U6<>"",学校マスタ!$R6<F$3+7,学校マスタ!$U6>=F$3),"▒",""))))) | G8: =IF(学校マスタ!$A6="","",IF(AND(学校マスタ!$U6<>"",学校マスタ!$U6>=G$3,学校マスタ!$U6<G$3+7),"◎",IF(OR(AND(学校マスタ!$H6<>"",学校マスタ!$H6>=G$3,学校マスタ!$H6<G$3+7),AND(学校マスタ!$J6<>"",学校マスタ!$J6>=G$3,学校マスタ!$J6<G$3+7),AND(学校マスタ!$L6<>"",学校マスタ!$L6>=G$3,学校マスタ!$L6<G$3+7)),"◆",IF(AND(学校マスタ!$O6<>"",学校マスタ!$P6<>"",学校マスタ!$O6<G$3+7,学校マスタ!$P6>=G$3),"█",IF(AND(学校マスタ!$R6<>"",学校マスタ!$U6<>"",学校マスタ!$R6<G$3+7,学校マスタ!$U6>=G$3),"▒",""))))) | H8: =IF(学校マスタ!$A6="","",IF(AND(学校マスタ!$U6<>"",学校マスタ!$U6>=H$3,学校マスタ!$U6<H$3+7),"◎",IF(OR(AND(学校マスタ!$H6<>"",学校マスタ!$H6>=H$3,学校マスタ!$H6<H$3+7),AND(学校マスタ!$J6<>"",学校マスタ!$J6>=H$3,学校マスタ!$J6<H$3+7),AND(学校マスタ!$L6<>"",学校マスタ!$L6>=H$3,学校マスタ!$L6<H$3+7)),"◆",IF(AND(学校マスタ!$O6<>"",学校マスタ!$P6<>"",学校マスタ!$O6<H$3+7,学校マスタ!$P6>=H$3),"█",IF(AND(学校マスタ!$R6<>"",学校マスタ!$U6<>"",学校マスタ!$R6<H$3+7,学校マスタ!$U6>=H$3),"▒",""))))) | I8: =IF(学校マスタ!$A6="","",IF(AND(学校マスタ!$U6<>"",学校マスタ!$U6>=I$3,学校マスタ!$U6<I$3+7),"◎",IF(OR(AND(学校マスタ!$H6<>"",学校マスタ!$H6>=I$3,学校マスタ!$H6<I$3+7),AND(学校マスタ!$J6<>"",学校マスタ!$J6>=I$3,学校マスタ!$J6<I$3+7),AND(学校マスタ!$L6<>"",学校マスタ!$L6>=I$3,学校マスタ!$L6<I$3+7)),"◆",IF(AND(学校マスタ!$O6<>"",学校マスタ!$P6<>"",学校マスタ!$O6<I$3+7,学校マスタ!$P6>=I$3),"█",IF(AND(学校マスタ!$R6<>"",学校マスタ!$U6<>"",学校マスタ!$R6<I$3+7,学校マスタ!$U6>=I$3),"▒",""))))) | J8: =IF(学校マスタ!$A6="","",IF(AND(学校マスタ!$U6<>"",学校マスタ!$U6>=J$3,学校マスタ!$U6<J$3+7),"◎",IF(OR(AND(学校マスタ!$H6<>"",学校マスタ!$H6>=J$3,学校マスタ!$H6<J$3+7),AND(学校マスタ!$J6<>"",学校マスタ!$J6>=J$3,学校マスタ!$J6<J$3+7),AND(学校マスタ!$L6<>"",学校マスタ!$L6>=J$3,学校マスタ!$L6<J$3+7)),"◆",IF(AND(学校マスタ!$O6<>"",学校マスタ!$P6<>"",学校マスタ!$O6<J$3+7,学校マスタ!$P6>=J$3),"█",IF(AND(学校マスタ!$R6<>"",学校マスタ!$U6<>"",学校マスタ!$R6<J$3+7,学校マスタ!$U6>=J$3),"▒",""))))) | K8: =IF(学校マスタ!$A6="","",IF(AND(学校マスタ!$U6<>"",学校マスタ!$U6>=K$3,学校マスタ!$U6<K$3+7),"◎",IF(OR(AND(学校マスタ!$H6<>"",学校マスタ!$H6>=K$3,学校マスタ!$H6<K$3+7),AND(学校マスタ!$J6<>"",学校マスタ!$J6>=K$3,学校マスタ!$J6<K$3+7),AND(学校マスタ!$L6<>"",学校マスタ!$L6>=K$3,学校マスタ!$L6<K$3+7)),"◆",IF(AND(学校マスタ!$O6<>"",学校マスタ!$P6<>"",学校マスタ!$O6<K$3+7,学校マスタ!$P6>=K$3),"█",IF(AND(学校マスタ!$R6<>"",学校マスタ!$U6<>"",学校マスタ!$R6<K$3+7,学校マスタ!$U6>=K$3),"▒",""))))) | L8: =IF(学校マスタ!$A6="","",IF(AND(学校マスタ!$U6<>"",学校マスタ!$U6>=L$3,学校マスタ!$U6<L$3+7),"◎",IF(OR(AND(学校マスタ!$H6<>"",学校マスタ!$H6>=L$3,学校マスタ!$H6<L$3+7),AND(学校マスタ!$J6<>"",学校マスタ!$J6>=L$3,学校マスタ!$J6<L$3+7),AND(学校マスタ!$L6<>"",学校マスタ!$L6>=L$3,学校マスタ!$L6<L$3+7)),"◆",IF(AND(学校マスタ!$O6<>"",学校マスタ!$P6<>"",学校マスタ!$O6<L$3+7,学校マスタ!$P6>=L$3),"█",IF(AND(学校マスタ!$R6<>"",学校マスタ!$U6<>"",学校マスタ!$R6<L$3+7,学校マスタ!$U6>=L$3),"▒",""))))) | ... AB8: =IF(学校マスタ!$A6="","",IF(AND(学校マスタ!$U6<>"",学校マスタ!$U6>=AB$3,学校マスタ!$U6<AB$3+7),"◎",IF(OR(AND(学校マスタ!$H6<>"",学校マスタ!$H6>=AB$3,学校マスタ!$H6<AB$3+7),AND(学校マスタ!$J6<>"",学校マスタ!$J6>=AB$3,学校マスタ!$J6<AB$3+7),AND(学校マスタ!$L6<>"",学校マスタ!$L6>=AB$3,学校マスタ!$L6<AB$3+7)),"◆",IF(AND(学校マスタ!$O6<>"",学校マスタ!$P6<>"",学校マスタ!$O6<AB$3+7,学校マスタ!$P6>=AB$3),"█",IF(AND(学校マスタ!$R6<>"",学校マスタ!$U6<>"",学校マスタ!$R6<AB$3+7,学校マスタ!$U6>=AB$3),"▒","")))))
A9: =IF(学校マスタ!$A7="","",学校マスタ!$A7) | B9: =IF(学校マスタ!$A7="","",学校マスタ!$C7) | C9: =IF(学校マスタ!$A7="","",学校マスタ!$X7) | D9: =IF(学校マスタ!$A7="","",学校マスタ!$R7) | E9: =IF(学校マスタ!$A7="","",IF(AND(学校マスタ!$U7<>"",学校マスタ!$U7>=E$3,学校マスタ!$U7<E$3+7),"◎",IF(OR(AND(学校マスタ!$H7<>"",学校マスタ!$H7>=E$3,学校マスタ!$H7<E$3+7),AND(学校マスタ!$J7<>"",学校マスタ!$J7>=E$3,学校マスタ!$J7<E$3+7),AND(学校マスタ!$L7<>"",学校マスタ!$L7>=E$3,学校マスタ!$L7<E$3+7)),"◆",IF(AND(学校マスタ!$O7<>"",学校マスタ!$P7<>"",学校マスタ!$O7<E$3+7,学校マスタ!$P7>=E$3),"█",IF(AND(学校マスタ!$R7<>"",学校マスタ!$U7<>"",学校マスタ!$R7<E$3+7,学校マスタ!$U7>=E$3),"▒",""))))) | F9: =IF(学校マスタ!$A7="","",IF(AND(学校マスタ!$U7<>"",学校マスタ!$U7>=F$3,学校マスタ!$U7<F$3+7),"◎",IF(OR(AND(学校マスタ!$H7<>"",学校マスタ!$H7>=F$3,学校マスタ!$H7<F$3+7),AND(学校マスタ!$J7<>"",学校マスタ!$J7>=F$3,学校マスタ!$J7<F$3+7),AND(学校マスタ!$L7<>"",学校マスタ!$L7>=F$3,学校マスタ!$L7<F$3+7)),"◆",IF(AND(学校マスタ!$O7<>"",学校マスタ!$P7<>"",学校マスタ!$O7<F$3+7,学校マスタ!$P7>=F$3),"█",IF(AND(学校マスタ!$R7<>"",学校マスタ!$U7<>"",学校マスタ!$R7<F$3+7,学校マスタ!$U7>=F$3),"▒",""))))) | G9: =IF(学校マスタ!$A7="","",IF(AND(学校マスタ!$U7<>"",学校マスタ!$U7>=G$3,学校マスタ!$U7<G$3+7),"◎",IF(OR(AND(学校マスタ!$H7<>"",学校マスタ!$H7>=G$3,学校マスタ!$H7<G$3+7),AND(学校マスタ!$J7<>"",学校マスタ!$J7>=G$3,学校マスタ!$J7<G$3+7),AND(学校マスタ!$L7<>"",学校マスタ!$L7>=G$3,学校マスタ!$L7<G$3+7)),"◆",IF(AND(学校マスタ!$O7<>"",学校マスタ!$P7<>"",学校マスタ!$O7<G$3+7,学校マスタ!$P7>=G$3),"█",IF(AND(学校マスタ!$R7<>"",学校マスタ!$U7<>"",学校マスタ!$R7<G$3+7,学校マスタ!$U7>=G$3),"▒",""))))) | H9: =IF(学校マスタ!$A7="","",IF(AND(学校マスタ!$U7<>"",学校マスタ!$U7>=H$3,学校マスタ!$U7<H$3+7),"◎",IF(OR(AND(学校マスタ!$H7<>"",学校マスタ!$H7>=H$3,学校マスタ!$H7<H$3+7),AND(学校マスタ!$J7<>"",学校マスタ!$J7>=H$3,学校マスタ!$J7<H$3+7),AND(学校マスタ!$L7<>"",学校マスタ!$L7>=H$3,学校マスタ!$L7<H$3+7)),"◆",IF(AND(学校マスタ!$O7<>"",学校マスタ!$P7<>"",学校マスタ!$O7<H$3+7,学校マスタ!$P7>=H$3),"█",IF(AND(学校マスタ!$R7<>"",学校マスタ!$U7<>"",学校マスタ!$R7<H$3+7,学校マスタ!$U7>=H$3),"▒",""))))) | I9: =IF(学校マスタ!$A7="","",IF(AND(学校マスタ!$U7<>"",学校マスタ!$U7>=I$3,学校マスタ!$U7<I$3+7),"◎",IF(OR(AND(学校マスタ!$H7<>"",学校マスタ!$H7>=I$3,学校マスタ!$H7<I$3+7),AND(学校マスタ!$J7<>"",学校マスタ!$J7>=I$3,学校マスタ!$J7<I$3+7),AND(学校マスタ!$L7<>"",学校マスタ!$L7>=I$3,学校マスタ!$L7<I$3+7)),"◆",IF(AND(学校マスタ!$O7<>"",学校マスタ!$P7<>"",学校マスタ!$O7<I$3+7,学校マスタ!$P7>=I$3),"█",IF(AND(学校マスタ!$R7<>"",学校マスタ!$U7<>"",学校マスタ!$R7<I$3+7,学校マスタ!$U7>=I$3),"▒",""))))) | J9: =IF(学校マスタ!$A7="","",IF(AND(学校マスタ!$U7<>"",学校マスタ!$U7>=J$3,学校マスタ!$U7<J$3+7),"◎",IF(OR(AND(学校マスタ!$H7<>"",学校マスタ!$H7>=J$3,学校マスタ!$H7<J$3+7),AND(学校マスタ!$J7<>"",学校マスタ!$J7>=J$3,学校マスタ!$J7<J$3+7),AND(学校マスタ!$L7<>"",学校マスタ!$L7>=J$3,学校マスタ!$L7<J$3+7)),"◆",IF(AND(学校マスタ!$O7<>"",学校マスタ!$P7<>"",学校マスタ!$O7<J$3+7,学校マスタ!$P7>=J$3),"█",IF(AND(学校マスタ!$R7<>"",学校マスタ!$U7<>"",学校マスタ!$R7<J$3+7,学校マスタ!$U7>=J$3),"▒",""))))) | K9: =IF(学校マスタ!$A7="","",IF(AND(学校マスタ!$U7<>"",学校マスタ!$U7>=K$3,学校マスタ!$U7<K$3+7),"◎",IF(OR(AND(学校マスタ!$H7<>"",学校マスタ!$H7>=K$3,学校マスタ!$H7<K$3+7),AND(学校マスタ!$J7<>"",学校マスタ!$J7>=K$3,学校マスタ!$J7<K$3+7),AND(学校マスタ!$L7<>"",学校マスタ!$L7>=K$3,学校マスタ!$L7<K$3+7)),"◆",IF(AND(学校マスタ!$O7<>"",学校マスタ!$P7<>"",学校マスタ!$O7<K$3+7,学校マスタ!$P7>=K$3),"█",IF(AND(学校マスタ!$R7<>"",学校マスタ!$U7<>"",学校マスタ!$R7<K$3+7,学校マスタ!$U7>=K$3),"▒",""))))) | L9: =IF(学校マスタ!$A7="","",IF(AND(学校マスタ!$U7<>"",学校マスタ!$U7>=L$3,学校マスタ!$U7<L$3+7),"◎",IF(OR(AND(学校マスタ!$H7<>"",学校マスタ!$H7>=L$3,学校マスタ!$H7<L$3+7),AND(学校マスタ!$J7<>"",学校マスタ!$J7>=L$3,学校マスタ!$J7<L$3+7),AND(学校マスタ!$L7<>"",学校マスタ!$L7>=L$3,学校マスタ!$L7<L$3+7)),"◆",IF(AND(学校マスタ!$O7<>"",学校マスタ!$P7<>"",学校マスタ!$O7<L$3+7,学校マスタ!$P7>=L$3),"█",IF(AND(学校マスタ!$R7<>"",学校マスタ!$U7<>"",学校マスタ!$R7<L$3+7,学校マスタ!$U7>=L$3),"▒",""))))) | ... AB9: =IF(学校マスタ!$A7="","",IF(AND(学校マスタ!$U7<>"",学校マスタ!$U7>=AB$3,学校マスタ!$U7<AB$3+7),"◎",IF(OR(AND(学校マスタ!$H7<>"",学校マスタ!$H7>=AB$3,学校マスタ!$H7<AB$3+7),AND(学校マスタ!$J7<>"",学校マスタ!$J7>=AB$3,学校マスタ!$J7<AB$3+7),AND(学校マスタ!$L7<>"",学校マスタ!$L7>=AB$3,学校マスタ!$L7<AB$3+7)),"◆",IF(AND(学校マスタ!$O7<>"",学校マスタ!$P7<>"",学校マスタ!$O7<AB$3+7,学校マスタ!$P7>=AB$3),"█",IF(AND(学校マスタ!$R7<>"",学校マスタ!$U7<>"",学校マスタ!$R7<AB$3+7,学校マスタ!$U7>=AB$3),"▒","")))))
A10: =IF(学校マスタ!$A8="","",学校マスタ!$A8) | B10: =IF(学校マスタ!$A8="","",学校マスタ!$C8) | C10: =IF(学校マスタ!$A8="","",学校マスタ!$X8) | D10: =IF(学校マスタ!$A8="","",学校マスタ!$R8) | E10: =IF(学校マスタ!$A8="","",IF(AND(学校マスタ!$U8<>"",学校マスタ!$U8>=E$3,学校マスタ!$U8<E$3+7),"◎",IF(OR(AND(学校マスタ!$H8<>"",学校マスタ!$H8>=E$3,学校マスタ!$H8<E$3+7),AND(学校マスタ!$J8<>"",学校マスタ!$J8>=E$3,学校マスタ!$J8<E$3+7),AND(学校マスタ!$L8<>"",学校マスタ!$L8>=E$3,学校マスタ!$L8<E$3+7)),"◆",IF(AND(学校マスタ!$O8<>"",学校マスタ!$P8<>"",学校マスタ!$O8<E$3+7,学校マスタ!$P8>=E$3),"█",IF(AND(学校マスタ!$R8<>"",学校マスタ!$U8<>"",学校マスタ!$R8<E$3+7,学校マスタ!$U8>=E$3),"▒",""))))) | F10: =IF(学校マスタ!$A8="","",IF(AND(学校マスタ!$U8<>"",学校マスタ!$U8>=F$3,学校マスタ!$U8<F$3+7),"◎",IF(OR(AND(学校マスタ!$H8<>"",学校マスタ!$H8>=F$3,学校マスタ!$H8<F$3+7),AND(学校マスタ!$J8<>"",学校マスタ!$J8>=F$3,学校マスタ!$J8<F$3+7),AND(学校マスタ!$L8<>"",学校マスタ!$L8>=F$3,学校マスタ!$L8<F$3+7)),"◆",IF(AND(学校マスタ!$O8<>"",学校マスタ!$P8<>"",学校マスタ!$O8<F$3+7,学校マスタ!$P8>=F$3),"█",IF(AND(学校マスタ!$R8<>"",学校マスタ!$U8<>"",学校マスタ!$R8<F$3+7,学校マスタ!$U8>=F$3),"▒",""))))) | G10: =IF(学校マスタ!$A8="","",IF(AND(学校マスタ!$U8<>"",学校マスタ!$U8>=G$3,学校マスタ!$U8<G$3+7),"◎",IF(OR(AND(学校マスタ!$H8<>"",学校マスタ!$H8>=G$3,学校マスタ!$H8<G$3+7),AND(学校マスタ!$J8<>"",学校マスタ!$J8>=G$3,学校マスタ!$J8<G$3+7),AND(学校マスタ!$L8<>"",学校マスタ!$L8>=G$3,学校マスタ!$L8<G$3+7)),"◆",IF(AND(学校マスタ!$O8<>"",学校マスタ!$P8<>"",学校マスタ!$O8<G$3+7,学校マスタ!$P8>=G$3),"█",IF(AND(学校マスタ!$R8<>"",学校マスタ!$U8<>"",学校マスタ!$R8<G$3+7,学校マスタ!$U8>=G$3),"▒",""))))) | H10: =IF(学校マスタ!$A8="","",IF(AND(学校マスタ!$U8<>"",学校マスタ!$U8>=H$3,学校マスタ!$U8<H$3+7),"◎",IF(OR(AND(学校マスタ!$H8<>"",学校マスタ!$H8>=H$3,学校マスタ!$H8<H$3+7),AND(学校マスタ!$J8<>"",学校マスタ!$J8>=H$3,学校マスタ!$J8<H$3+7),AND(学校マスタ!$L8<>"",学校マスタ!$L8>=H$3,学校マスタ!$L8<H$3+7)),"◆",IF(AND(学校マスタ!$O8<>"",学校マスタ!$P8<>"",学校マスタ!$O8<H$3+7,学校マスタ!$P8>=H$3),"█",IF(AND(学校マスタ!$R8<>"",学校マスタ!$U8<>"",学校マスタ!$R8<H$3+7,学校マスタ!$U8>=H$3),"▒",""))))) | I10: =IF(学校マスタ!$A8="","",IF(AND(学校マスタ!$U8<>"",学校マスタ!$U8>=I$3,学校マスタ!$U8<I$3+7),"◎",IF(OR(AND(学校マスタ!$H8<>"",学校マスタ!$H8>=I$3,学校マスタ!$H8<I$3+7),AND(学校マスタ!$J8<>"",学校マスタ!$J8>=I$3,学校マスタ!$J8<I$3+7),AND(学校マスタ!$L8<>"",学校マスタ!$L8>=I$3,学校マスタ!$L8<I$3+7)),"◆",IF(AND(学校マスタ!$O8<>"",学校マスタ!$P8<>"",学校マスタ!$O8<I$3+7,学校マスタ!$P8>=I$3),"█",IF(AND(学校マスタ!$R8<>"",学校マスタ!$U8<>"",学校マスタ!$R8<I$3+7,学校マスタ!$U8>=I$3),"▒",""))))) | J10: =IF(学校マスタ!$A8="","",IF(AND(学校マスタ!$U8<>"",学校マスタ!$U8>=J$3,学校マスタ!$U8<J$3+7),"◎",IF(OR(AND(学校マスタ!$H8<>"",学校マスタ!$H8>=J$3,学校マスタ!$H8<J$3+7),AND(学校マスタ!$J8<>"",学校マスタ!$J8>=J$3,学校マスタ!$J8<J$3+7),AND(学校マスタ!$L8<>"",学校マスタ!$L8>=J$3,学校マスタ!$L8<J$3+7)),"◆",IF(AND(学校マスタ!$O8<>"",学校マスタ!$P8<>"",学校マスタ!$O8<J$3+7,学校マスタ!$P8>=J$3),"█",IF(AND(学校マスタ!$R8<>"",学校マスタ!$U8<>"",学校マスタ!$R8<J$3+7,学校マスタ!$U8>=J$3),"▒",""))))) | K10: =IF(学校マスタ!$A8="","",IF(AND(学校マスタ!$U8<>"",学校マスタ!$U8>=K$3,学校マスタ!$U8<K$3+7),"◎",IF(OR(AND(学校マスタ!$H8<>"",学校マスタ!$H8>=K$3,学校マスタ!$H8<K$3+7),AND(学校マスタ!$J8<>"",学校マスタ!$J8>=K$3,学校マスタ!$J8<K$3+7),AND(学校マスタ!$L8<>"",学校マスタ!$L8>=K$3,学校マスタ!$L8<K$3+7)),"◆",IF(AND(学校マスタ!$O8<>"",学校マスタ!$P8<>"",学校マスタ!$O8<K$3+7,学校マスタ!$P8>=K$3),"█",IF(AND(学校マスタ!$R8<>"",学校マスタ!$U8<>"",学校マスタ!$R8<K$3+7,学校マスタ!$U8>=K$3),"▒",""))))) | L10: =IF(学校マスタ!$A8="","",IF(AND(学校マスタ!$U8<>"",学校マスタ!$U8>=L$3,学校マスタ!$U8<L$3+7),"◎",IF(OR(AND(学校マスタ!$H8<>"",学校マスタ!$H8>=L$3,学校マスタ!$H8<L$3+7),AND(学校マスタ!$J8<>"",学校マスタ!$J8>=L$3,学校マスタ!$J8<L$3+7),AND(学校マスタ!$L8<>"",学校マスタ!$L8>=L$3,学校マスタ!$L8<L$3+7)),"◆",IF(AND(学校マスタ!$O8<>"",学校マスタ!$P8<>"",学校マスタ!$O8<L$3+7,学校マスタ!$P8>=L$3),"█",IF(AND(学校マスタ!$R8<>"",学校マスタ!$U8<>"",学校マスタ!$R8<L$3+7,学校マスタ!$U8>=L$3),"▒",""))))) | ... AB10: =IF(学校マスタ!$A8="","",IF(AND(学校マスタ!$U8<>"",学校マスタ!$U8>=AB$3,学校マスタ!$U8<AB$3+7),"◎",IF(OR(AND(学校マスタ!$H8<>"",学校マスタ!$H8>=AB$3,学校マスタ!$H8<AB$3+7),AND(学校マスタ!$J8<>"",学校マスタ!$J8>=AB$3,学校マスタ!$J8<AB$3+7),AND(学校マスタ!$L8<>"",学校マスタ!$L8>=AB$3,学校マスタ!$L8<AB$3+7)),"◆",IF(AND(学校マスタ!$O8<>"",学校マスタ!$P8<>"",学校マスタ!$O8<AB$3+7,学校マスタ!$P8>=AB$3),"█",IF(AND(学校マスタ!$R8<>"",学校マスタ!$U8<>"",学校マスタ!$R8<AB$3+7,学校マスタ!$U8>=AB$3),"▒","")))))
A11: =IF(学校マスタ!$A9="","",学校マスタ!$A9) | B11: =IF(学校マスタ!$A9="","",学校マスタ!$C9) | C11: =IF(学校マスタ!$A9="","",学校マスタ!$X9) | D11: =IF(学校マスタ!$A9="","",学校マスタ!$R9) | E11: =IF(学校マスタ!$A9="","",IF(AND(学校マスタ!$U9<>"",学校マスタ!$U9>=E$3,学校マスタ!$U9<E$3+7),"◎",IF(OR(AND(学校マスタ!$H9<>"",学校マスタ!$H9>=E$3,学校マスタ!$H9<E$3+7),AND(学校マスタ!$J9<>"",学校マスタ!$J9>=E$3,学校マスタ!$J9<E$3+7),AND(学校マスタ!$L9<>"",学校マスタ!$L9>=E$3,学校マスタ!$L9<E$3+7)),"◆",IF(AND(学校マスタ!$O9<>"",学校マスタ!$P9<>"",学校マスタ!$O9<E$3+7,学校マスタ!$P9>=E$3),"█",IF(AND(学校マスタ!$R9<>"",学校マスタ!$U9<>"",学校マスタ!$R9<E$3+7,学校マスタ!$U9>=E$3),"▒",""))))) | F11: =IF(学校マスタ!$A9="","",IF(AND(学校マスタ!$U9<>"",学校マスタ!$U9>=F$3,学校マスタ!$U9<F$3+7),"◎",IF(OR(AND(学校マスタ!$H9<>"",学校マスタ!$H9>=F$3,学校マスタ!$H9<F$3+7),AND(学校マスタ!$J9<>"",学校マスタ!$J9>=F$3,学校マスタ!$J9<F$3+7),AND(学校マスタ!$L9<>"",学校マスタ!$L9>=F$3,学校マスタ!$L9<F$3+7)),"◆",IF(AND(学校マスタ!$O9<>"",学校マスタ!$P9<>"",学校マスタ!$O9<F$3+7,学校マスタ!$P9>=F$3),"█",IF(AND(学校マスタ!$R9<>"",学校マスタ!$U9<>"",学校マスタ!$R9<F$3+7,学校マスタ!$U9>=F$3),"▒",""))))) | G11: =IF(学校マスタ!$A9="","",IF(AND(学校マスタ!$U9<>"",学校マスタ!$U9>=G$3,学校マスタ!$U9<G$3+7),"◎",IF(OR(AND(学校マスタ!$H9<>"",学校マスタ!$H9>=G$3,学校マスタ!$H9<G$3+7),AND(学校マスタ!$J9<>"",学校マスタ!$J9>=G$3,学校マスタ!$J9<G$3+7),AND(学校マスタ!$L9<>"",学校マスタ!$L9>=G$3,学校マスタ!$L9<G$3+7)),"◆",IF(AND(学校マスタ!$O9<>"",学校マスタ!$P9<>"",学校マスタ!$O9<G$3+7,学校マスタ!$P9>=G$3),"█",IF(AND(学校マスタ!$R9<>"",学校マスタ!$U9<>"",学校マスタ!$R9<G$3+7,学校マスタ!$U9>=G$3),"▒",""))))) | H11: =IF(学校マスタ!$A9="","",IF(AND(学校マスタ!$U9<>"",学校マスタ!$U9>=H$3,学校マスタ!$U9<H$3+7),"◎",IF(OR(AND(学校マスタ!$H9<>"",学校マスタ!$H9>=H$3,学校マスタ!$H9<H$3+7),AND(学校マスタ!$J9<>"",学校マスタ!$J9>=H$3,学校マスタ!$J9<H$3+7),AND(学校マスタ!$L9<>"",学校マスタ!$L9>=H$3,学校マスタ!$L9<H$3+7)),"◆",IF(AND(学校マスタ!$O9<>"",学校マスタ!$P9<>"",学校マスタ!$O9<H$3+7,学校マスタ!$P9>=H$3),"█",IF(AND(学校マスタ!$R9<>"",学校マスタ!$U9<>"",学校マスタ!$R9<H$3+7,学校マスタ!$U9>=H$3),"▒",""))))) | I11: =IF(学校マスタ!$A9="","",IF(AND(学校マスタ!$U9<>"",学校マスタ!$U9>=I$3,学校マスタ!$U9<I$3+7),"◎",IF(OR(AND(学校マスタ!$H9<>"",学校マスタ!$H9>=I$3,学校マスタ!$H9<I$3+7),AND(学校マスタ!$J9<>"",学校マスタ!$J9>=I$3,学校マスタ!$J9<I$3+7),AND(学校マスタ!$L9<>"",学校マスタ!$L9>=I$3,学校マスタ!$L9<I$3+7)),"◆",IF(AND(学校マスタ!$O9<>"",学校マスタ!$P9<>"",学校マスタ!$O9<I$3+7,学校マスタ!$P9>=I$3),"█",IF(AND(学校マスタ!$R9<>"",学校マスタ!$U9<>"",学校マスタ!$R9<I$3+7,学校マスタ!$U9>=I$3),"▒",""))))) | J11: =IF(学校マスタ!$A9="","",IF(AND(学校マスタ!$U9<>"",学校マスタ!$U9>=J$3,学校マスタ!$U9<J$3+7),"◎",IF(OR(AND(学校マスタ!$H9<>"",学校マスタ!$H9>=J$3,学校マスタ!$H9<J$3+7),AND(学校マスタ!$J9<>"",学校マスタ!$J9>=J$3,学校マスタ!$J9<J$3+7),AND(学校マスタ!$L9<>"",学校マスタ!$L9>=J$3,学校マスタ!$L9<J$3+7)),"◆",IF(AND(学校マスタ!$O9<>"",学校マスタ!$P9<>"",学校マスタ!$O9<J$3+7,学校マスタ!$P9>=J$3),"█",IF(AND(学校マスタ!$R9<>"",学校マスタ!$U9<>"",学校マスタ!$R9<J$3+7,学校マスタ!$U9>=J$3),"▒",""))))) | K11: =IF(学校マスタ!$A9="","",IF(AND(学校マスタ!$U9<>"",学校マスタ!$U9>=K$3,学校マスタ!$U9<K$3+7),"◎",IF(OR(AND(学校マスタ!$H9<>"",学校マスタ!$H9>=K$3,学校マスタ!$H9<K$3+7),AND(学校マスタ!$J9<>"",学校マスタ!$J9>=K$3,学校マスタ!$J9<K$3+7),AND(学校マスタ!$L9<>"",学校マスタ!$L9>=K$3,学校マスタ!$L9<K$3+7)),"◆",IF(AND(学校マスタ!$O9<>"",学校マスタ!$P9<>"",学校マスタ!$O9<K$3+7,学校マスタ!$P9>=K$3),"█",IF(AND(学校マスタ!$R9<>"",学校マスタ!$U9<>"",学校マスタ!$R9<K$3+7,学校マスタ!$U9>=K$3),"▒",""))))) | L11: =IF(学校マスタ!$A9="","",IF(AND(学校マスタ!$U9<>"",学校マスタ!$U9>=L$3,学校マスタ!$U9<L$3+7),"◎",IF(OR(AND(学校マスタ!$H9<>"",学校マスタ!$H9>=L$3,学校マスタ!$H9<L$3+7),AND(学校マスタ!$J9<>"",学校マスタ!$J9>=L$3,学校マスタ!$J9<L$3+7),AND(学校マスタ!$L9<>"",学校マスタ!$L9>=L$3,学校マスタ!$L9<L$3+7)),"◆",IF(AND(学校マスタ!$O9<>"",学校マスタ!$P9<>"",学校マスタ!$O9<L$3+7,学校マスタ!$P9>=L$3),"█",IF(AND(学校マスタ!$R9<>"",学校マスタ!$U9<>"",学校マスタ!$R9<L$3+7,学校マスタ!$U9>=L$3),"▒",""))))) | ... AB11: =IF(学校マスタ!$A9="","",IF(AND(学校マスタ!$U9<>"",学校マスタ!$U9>=AB$3,学校マスタ!$U9<AB$3+7),"◎",IF(OR(AND(学校マスタ!$H9<>"",学校マスタ!$H9>=AB$3,学校マスタ!$H9<AB$3+7),AND(学校マスタ!$J9<>"",学校マスタ!$J9>=AB$3,学校マスタ!$J9<AB$3+7),AND(学校マスタ!$L9<>"",学校マスタ!$L9>=AB$3,学校マスタ!$L9<AB$3+7)),"◆",IF(AND(学校マスタ!$O9<>"",学校マスタ!$P9<>"",学校マスタ!$O9<AB$3+7,学校マスタ!$P9>=AB$3),"█",IF(AND(学校マスタ!$R9<>"",学校マスタ!$U9<>"",学校マスタ!$R9<AB$3+7,学校マスタ!$U9>=AB$3),"▒","")))))
A12: =IF(学校マスタ!$A10="","",学校マスタ!$A10) | B12: =IF(学校マスタ!$A10="","",学校マスタ!$C10) | C12: =IF(学校マスタ!$A10="","",学校マスタ!$X10) | D12: =IF(学校マスタ!$A10="","",学校マスタ!$R10) | E12: =IF(学校マスタ!$A10="","",IF(AND(学校マスタ!$U10<>"",学校マスタ!$U10>=E$3,学校マスタ!$U10<E$3+7),"◎",IF(OR(AND(学校マスタ!$H10<>"",学校マスタ!$H10>=E$3,学校マスタ!$H10<E$3+7),AND(学校マスタ!$J10<>"",学校マスタ!$J10>=E$3,学校マスタ!$J10<E$3+7),AND(学校マスタ!$L10<>"",学校マスタ!$L10>=E$3,学校マスタ!$L10<E$3+7)),"◆",IF(AND(学校マスタ!$O10<>"",学校マスタ!$P10<>"",学校マスタ!$O10<E$3+7,学校マスタ!$P10>=E$3),"█",IF(AND(学校マスタ!$R10<>"",学校マスタ!$U10<>"",学校マスタ!$R10<E$3+7,学校マスタ!$U10>=E$3),"▒",""))))) | F12: =IF(学校マスタ!$A10="","",IF(AND(学校マスタ!$U10<>"",学校マスタ!$U10>=F$3,学校マスタ!$U10<F$3+7),"◎",IF(OR(AND(学校マスタ!$H10<>"",学校マスタ!$H10>=F$3,学校マスタ!$H10<F$3+7),AND(学校マスタ!$J10<>"",学校マスタ!$J10>=F$3,学校マスタ!$J10<F$3+7),AND(学校マスタ!$L10<>"",学校マスタ!$L10>=F$3,学校マスタ!$L10<F$3+7)),"◆",IF(AND(学校マスタ!$O10<>"",学校マスタ!$P10<>"",学校マスタ!$O10<F$3+7,学校マスタ!$P10>=F$3),"█",IF(AND(学校マスタ!$R10<>"",学校マスタ!$U10<>"",学校マスタ!$R10<F$3+7,学校マスタ!$U10>=F$3),"▒",""))))) | G12: =IF(学校マスタ!$A10="","",IF(AND(学校マスタ!$U10<>"",学校マスタ!$U10>=G$3,学校マスタ!$U10<G$3+7),"◎",IF(OR(AND(学校マスタ!$H10<>"",学校マスタ!$H10>=G$3,学校マスタ!$H10<G$3+7),AND(学校マスタ!$J10<>"",学校マスタ!$J10>=G$3,学校マスタ!$J10<G$3+7),AND(学校マスタ!$L10<>"",学校マスタ!$L10>=G$3,学校マスタ!$L10<G$3+7)),"◆",IF(AND(学校マスタ!$O10<>"",学校マスタ!$P10<>"",学校マスタ!$O10<G$3+7,学校マスタ!$P10>=G$3),"█",IF(AND(学校マスタ!$R10<>"",学校マスタ!$U10<>"",学校マスタ!$R10<G$3+7,学校マスタ!$U10>=G$3),"▒",""))))) | H12: =IF(学校マスタ!$A10="","",IF(AND(学校マスタ!$U10<>"",学校マスタ!$U10>=H$3,学校マスタ!$U10<H$3+7),"◎",IF(OR(AND(学校マスタ!$H10<>"",学校マスタ!$H10>=H$3,学校マスタ!$H10<H$3+7),AND(学校マスタ!$J10<>"",学校マスタ!$J10>=H$3,学校マスタ!$J10<H$3+7),AND(学校マスタ!$L10<>"",学校マスタ!$L10>=H$3,学校マスタ!$L10<H$3+7)),"◆",IF(AND(学校マスタ!$O10<>"",学校マスタ!$P10<>"",学校マスタ!$O10<H$3+7,学校マスタ!$P10>=H$3),"█",IF(AND(学校マスタ!$R10<>"",学校マスタ!$U10<>"",学校マスタ!$R10<H$3+7,学校マスタ!$U10>=H$3),"▒",""))))) | I12: =IF(学校マスタ!$A10="","",IF(AND(学校マスタ!$U10<>"",学校マスタ!$U10>=I$3,学校マスタ!$U10<I$3+7),"◎",IF(OR(AND(学校マスタ!$H10<>"",学校マスタ!$H10>=I$3,学校マスタ!$H10<I$3+7),AND(学校マスタ!$J10<>"",学校マスタ!$J10>=I$3,学校マスタ!$J10<I$3+7),AND(学校マスタ!$L10<>"",学校マスタ!$L10>=I$3,学校マスタ!$L10<I$3+7)),"◆",IF(AND(学校マスタ!$O10<>"",学校マスタ!$P10<>"",学校マスタ!$O10<I$3+7,学校マスタ!$P10>=I$3),"█",IF(AND(学校マスタ!$R10<>"",学校マスタ!$U10<>"",学校マスタ!$R10<I$3+7,学校マスタ!$U10>=I$3),"▒",""))))) | J12: =IF(学校マスタ!$A10="","",IF(AND(学校マスタ!$U10<>"",学校マスタ!$U10>=J$3,学校マスタ!$U10<J$3+7),"◎",IF(OR(AND(学校マスタ!$H10<>"",学校マスタ!$H10>=J$3,学校マスタ!$H10<J$3+7),AND(学校マスタ!$J10<>"",学校マスタ!$J10>=J$3,学校マスタ!$J10<J$3+7),AND(学校マスタ!$L10<>"",学校マスタ!$L10>=J$3,学校マスタ!$L10<J$3+7)),"◆",IF(AND(学校マスタ!$O10<>"",学校マスタ!$P10<>"",学校マスタ!$O10<J$3+7,学校マスタ!$P10>=J$3),"█",IF(AND(学校マスタ!$R10<>"",学校マスタ!$U10<>"",学校マスタ!$R10<J$3+7,学校マスタ!$U10>=J$3),"▒",""))))) | K12: =IF(学校マスタ!$A10="","",IF(AND(学校マスタ!$U10<>"",学校マスタ!$U10>=K$3,学校マスタ!$U10<K$3+7),"◎",IF(OR(AND(学校マスタ!$H10<>"",学校マスタ!$H10>=K$3,学校マスタ!$H10<K$3+7),AND(学校マスタ!$J10<>"",学校マスタ!$J10>=K$3,学校マスタ!$J10<K$3+7),AND(学校マスタ!$L10<>"",学校マスタ!$L10>=K$3,学校マスタ!$L10<K$3+7)),"◆",IF(AND(学校マスタ!$O10<>"",学校マスタ!$P10<>"",学校マスタ!$O10<K$3+7,学校マスタ!$P10>=K$3),"█",IF(AND(学校マスタ!$R10<>"",学校マスタ!$U10<>"",学校マスタ!$R10<K$3+7,学校マスタ!$U10>=K$3),"▒",""))))) | L12: =IF(学校マスタ!$A10="","",IF(AND(学校マスタ!$U10<>"",学校マスタ!$U10>=L$3,学校マスタ!$U10<L$3+7),"◎",IF(OR(AND(学校マスタ!$H10<>"",学校マスタ!$H10>=L$3,学校マスタ!$H10<L$3+7),AND(学校マスタ!$J10<>"",学校マスタ!$J10>=L$3,学校マスタ!$J10<L$3+7),AND(学校マスタ!$L10<>"",学校マスタ!$L10>=L$3,学校マスタ!$L10<L$3+7)),"◆",IF(AND(学校マスタ!$O10<>"",学校マスタ!$P10<>"",学校マスタ!$O10<L$3+7,学校マスタ!$P10>=L$3),"█",IF(AND(学校マスタ!$R10<>"",学校マスタ!$U10<>"",学校マスタ!$R10<L$3+7,学校マスタ!$U10>=L$3),"▒",""))))) | ... AB12: =IF(学校マスタ!$A10="","",IF(AND(学校マスタ!$U10<>"",学校マスタ!$U10>=AB$3,学校マスタ!$U10<AB$3+7),"◎",IF(OR(AND(学校マスタ!$H10<>"",学校マスタ!$H10>=AB$3,学校マスタ!$H10<AB$3+7),AND(学校マスタ!$J10<>"",学校マスタ!$J10>=AB$3,学校マスタ!$J10<AB$3+7),AND(学校マスタ!$L10<>"",学校マスタ!$L10>=AB$3,学校マスタ!$L10<AB$3+7)),"◆",IF(AND(学校マスタ!$O10<>"",学校マスタ!$P10<>"",学校マスタ!$O10<AB$3+7,学校マスタ!$P10>=AB$3),"█",IF(AND(学校マスタ!$R10<>"",学校マスタ!$U10<>"",学校マスタ!$R10<AB$3+7,学校マスタ!$U10>=AB$3),"▒","")))))
A13: =IF(学校マスタ!$A11="","",学校マスタ!$A11) | B13: =IF(学校マスタ!$A11="","",学校マスタ!$C11) | C13: =IF(学校マスタ!$A11="","",学校マスタ!$X11) | D13: =IF(学校マスタ!$A11="","",学校マスタ!$R11) | E13: =IF(学校マスタ!$A11="","",IF(AND(学校マスタ!$U11<>"",学校マスタ!$U11>=E$3,学校マスタ!$U11<E$3+7),"◎",IF(OR(AND(学校マスタ!$H11<>"",学校マスタ!$H11>=E$3,学校マスタ!$H11<E$3+7),AND(学校マスタ!$J11<>"",学校マスタ!$J11>=E$3,学校マスタ!$J11<E$3+7),AND(学校マスタ!$L11<>"",学校マスタ!$L11>=E$3,学校マスタ!$L11<E$3+7)),"◆",IF(AND(学校マスタ!$O11<>"",学校マスタ!$P11<>"",学校マスタ!$O11<E$3+7,学校マスタ!$P11>=E$3),"█",IF(AND(学校マスタ!$R11<>"",学校マスタ!$U11<>"",学校マスタ!$R11<E$3+7,学校マスタ!$U11>=E$3),"▒",""))))) | F13: =IF(学校マスタ!$A11="","",IF(AND(学校マスタ!$U11<>"",学校マスタ!$U11>=F$3,学校マスタ!$U11<F$3+7),"◎",IF(OR(AND(学校マスタ!$H11<>"",学校マスタ!$H11>=F$3,学校マスタ!$H11<F$3+7),AND(学校マスタ!$J11<>"",学校マスタ!$J11>=F$3,学校マスタ!$J11<F$3+7),AND(学校マスタ!$L11<>"",学校マスタ!$L11>=F$3,学校マスタ!$L11<F$3+7)),"◆",IF(AND(学校マスタ!$O11<>"",学校マスタ!$P11<>"",学校マスタ!$O11<F$3+7,学校マスタ!$P11>=F$3),"█",IF(AND(学校マスタ!$R11<>"",学校マスタ!$U11<>"",学校マスタ!$R11<F$3+7,学校マスタ!$U11>=F$3),"▒",""))))) | G13: =IF(学校マスタ!$A11="","",IF(AND(学校マスタ!$U11<>"",学校マスタ!$U11>=G$3,学校マスタ!$U11<G$3+7),"◎",IF(OR(AND(学校マスタ!$H11<>"",学校マスタ!$H11>=G$3,学校マスタ!$H11<G$3+7),AND(学校マスタ!$J11<>"",学校マスタ!$J11>=G$3,学校マスタ!$J11<G$3+7),AND(学校マスタ!$L11<>"",学校マスタ!$L11>=G$3,学校マスタ!$L11<G$3+7)),"◆",IF(AND(学校マスタ!$O11<>"",学校マスタ!$P11<>"",学校マスタ!$O11<G$3+7,学校マスタ!$P11>=G$3),"█",IF(AND(学校マスタ!$R11<>"",学校マスタ!$U11<>"",学校マスタ!$R11<G$3+7,学校マスタ!$U11>=G$3),"▒",""))))) | H13: =IF(学校マスタ!$A11="","",IF(AND(学校マスタ!$U11<>"",学校マスタ!$U11>=H$3,学校マスタ!$U11<H$3+7),"◎",IF(OR(AND(学校マスタ!$H11<>"",学校マスタ!$H11>=H$3,学校マスタ!$H11<H$3+7),AND(学校マスタ!$J11<>"",学校マスタ!$J11>=H$3,学校マスタ!$J11<H$3+7),AND(学校マスタ!$L11<>"",学校マスタ!$L11>=H$3,学校マスタ!$L11<H$3+7)),"◆",IF(AND(学校マスタ!$O11<>"",学校マスタ!$P11<>"",学校マスタ!$O11<H$3+7,学校マスタ!$P11>=H$3),"█",IF(AND(学校マスタ!$R11<>"",学校マスタ!$U11<>"",学校マスタ!$R11<H$3+7,学校マスタ!$U11>=H$3),"▒",""))))) | I13: =IF(学校マスタ!$A11="","",IF(AND(学校マスタ!$U11<>"",学校マスタ!$U11>=I$3,学校マスタ!$U11<I$3+7),"◎",IF(OR(AND(学校マスタ!$H11<>"",学校マスタ!$H11>=I$3,学校マスタ!$H11<I$3+7),AND(学校マスタ!$J11<>"",学校マスタ!$J11>=I$3,学校マスタ!$J11<I$3+7),AND(学校マスタ!$L11<>"",学校マスタ!$L11>=I$3,学校マスタ!$L11<I$3+7)),"◆",IF(AND(学校マスタ!$O11<>"",学校マスタ!$P11<>"",学校マスタ!$O11<I$3+7,学校マスタ!$P11>=I$3),"█",IF(AND(学校マスタ!$R11<>"",学校マスタ!$U11<>"",学校マスタ!$R11<I$3+7,学校マスタ!$U11>=I$3),"▒",""))))) | J13: =IF(学校マスタ!$A11="","",IF(AND(学校マスタ!$U11<>"",学校マスタ!$U11>=J$3,学校マスタ!$U11<J$3+7),"◎",IF(OR(AND(学校マスタ!$H11<>"",学校マスタ!$H11>=J$3,学校マスタ!$H11<J$3+7),AND(学校マスタ!$J11<>"",学校マスタ!$J11>=J$3,学校マスタ!$J11<J$3+7),AND(学校マスタ!$L11<>"",学校マスタ!$L11>=J$3,学校マスタ!$L11<J$3+7)),"◆",IF(AND(学校マスタ!$O11<>"",学校マスタ!$P11<>"",学校マスタ!$O11<J$3+7,学校マスタ!$P11>=J$3),"█",IF(AND(学校マスタ!$R11<>"",学校マスタ!$U11<>"",学校マスタ!$R11<J$3+7,学校マスタ!$U11>=J$3),"▒",""))))) | K13: =IF(学校マスタ!$A11="","",IF(AND(学校マスタ!$U11<>"",学校マスタ!$U11>=K$3,学校マスタ!$U11<K$3+7),"◎",IF(OR(AND(学校マスタ!$H11<>"",学校マスタ!$H11>=K$3,学校マスタ!$H11<K$3+7),AND(学校マスタ!$J11<>"",学校マスタ!$J11>=K$3,学校マスタ!$J11<K$3+7),AND(学校マスタ!$L11<>"",学校マスタ!$L11>=K$3,学校マスタ!$L11<K$3+7)),"◆",IF(AND(学校マスタ!$O11<>"",学校マスタ!$P11<>"",学校マスタ!$O11<K$3+7,学校マスタ!$P11>=K$3),"█",IF(AND(学校マスタ!$R11<>"",学校マスタ!$U11<>"",学校マスタ!$R11<K$3+7,学校マスタ!$U11>=K$3),"▒",""))))) | L13: =IF(学校マスタ!$A11="","",IF(AND(学校マスタ!$U11<>"",学校マスタ!$U11>=L$3,学校マスタ!$U11<L$3+7),"◎",IF(OR(AND(学校マスタ!$H11<>"",学校マスタ!$H11>=L$3,学校マスタ!$H11<L$3+7),AND(学校マスタ!$J11<>"",学校マスタ!$J11>=L$3,学校マスタ!$J11<L$3+7),AND(学校マスタ!$L11<>"",学校マスタ!$L11>=L$3,学校マスタ!$L11<L$3+7)),"◆",IF(AND(学校マスタ!$O11<>"",学校マスタ!$P11<>"",学校マスタ!$O11<L$3+7,学校マスタ!$P11>=L$3),"█",IF(AND(学校マスタ!$R11<>"",学校マスタ!$U11<>"",学校マスタ!$R11<L$3+7,学校マスタ!$U11>=L$3),"▒",""))))) | ... AB13: =IF(学校マスタ!$A11="","",IF(AND(学校マスタ!$U11<>"",学校マスタ!$U11>=AB$3,学校マスタ!$U11<AB$3+7),"◎",IF(OR(AND(学校マスタ!$H11<>"",学校マスタ!$H11>=AB$3,学校マスタ!$H11<AB$3+7),AND(学校マスタ!$J11<>"",学校マスタ!$J11>=AB$3,学校マスタ!$J11<AB$3+7),AND(学校マスタ!$L11<>"",学校マスタ!$L11>=AB$3,学校マスタ!$L11<AB$3+7)),"◆",IF(AND(学校マスタ!$O11<>"",学校マスタ!$P11<>"",学校マスタ!$O11<AB$3+7,学校マスタ!$P11>=AB$3),"█",IF(AND(学校マスタ!$R11<>"",学校マスタ!$U11<>"",学校マスタ!$R11<AB$3+7,学校マスタ!$U11>=AB$3),"▒","")))))
